Workbook

Sheet Стан БГ
A1: Рівень натренованості льотного складу
A2: Стан на: | C2: 46058
A3: № п/п | B3: Посада | C3: П.І.Б. | D3: Військова класність | E3: Випробувальна класність | G3: Наявність | H3: Тип ЛА | I3: Перерви за МУ | U3: Перевірки за видами ЛП | AM3: Таблиця комісування | AW3: Перерви за видами ЛП
I4: День | O4: Ніч
I5: ПМУ | K5: СМУ | M5: ВМП | O5: ПМУ | Q5: СМУ | S5: ВМП
U6: Методика льотних випробувань | W6: Техніка пілотування | Y6: Захід на посадку за приладами | AA6: ТП за дублюючими приладами | AC6: ТП з ІВД | AE6: Повітряна навігація | AG6: Бойове застосівання | AI6: З інструкторського | AK6: З льотної підготовки | AM6: Аварійне залишення | AO6: Ст. 205 ПРІАЗ | AQ6: ЛЛК / УМО | AS6: Відпустка | AU6: Стрибки з парашютом | AW6: Складний пілотаж | AY6: ТП та навігація на малих висотах | BA6: ТП та навігація на ГМВ (з викор ОНБ) | BC6: Бойове застосування | BE6: Групова злітаність | BG6: Польоти на десантування | BI6: Політ на РСНГ
A8: Допустимі перерви | D8: 1 | I8: 107 | J8: 3,5 | K8: 92 | L8: 3,0 | M8: 77 | N8: 2,5 | O8: 92 | P8: 3,0 | Q8: 77 | R8: 2,5 | S8: 61 | T8: 2,0 | U8: 365 | V8: 12 | W8: 365 | X8: 12 | Y8: 365 | Z8: 12 | AA8: 365 | AB8: 12 | AC8: 365 | AD8: 12 | AE8: 365 | AF8: 12 | AG8: 365 | AH8: 12 | AI8: 365 | AJ8: 12 | AK8: 365 | AL8: 12 | AM8: 365 | AN8: 12 | AO8: 184 | AP8: 6 | AQ8: 365 | AR8: 12 | AS8: 365 | AT8: 12 | AU8: 1095 | AV8: 36 | AW8: 365 | AX8: 12 | AY8: 365 | AZ8: 12 | BA8: 122 | BB8: 4 | BC8: 184 | BD8: 6 | BE8: 184 | BF8: 6 | BG8: 365 | BH8: 12 | BI8: 184 | BJ8: 6
D9: 2 | I9: 92 | J9: 3,0 | K9: 77 | L9: 2,5 | M9: 61 | N9: 2,0 | O9: 77 | P9: 2,5 | Q9: 61 | R9: 2,0 | S9: 46 | T9: 1,5 | U9: 365 | V9: 12 | W9: 365 | X9: 12 | Y9: 365 | Z9: 12 | AA9: 365 | AB9: 12 | AC9: 365 | AD9: 12 | AE9: 365 | AF9: 12 | AG9: 365 | AH9: 12 | AI9: 365 | AJ9: 12 | AK9: 365 | AL9: 12 | AM9: 365 | AN9: 12 | AO9: 184 | AP9: 6 | AQ9: 365 | AR9: 12 | AS9: 365 | AT9: 12 | AU9: 1095 | AV9: 36 | AW9: 365 | AX9: 12 | AY9: 365 | AZ9: 12 | BA9: 122 | BB9: 4 | BC9: 184 | BD9: 6 | BE9: 184 | BF9: 6 | BG9: 365 | BH9: 12 | BI9: 184 | BJ9: 6
D10: 3 | I10: 76 | J10: 2,5 | K10: 61 | L10: 2 | M10: 46 | N10: 1,5 | O10: 61 | P10: 2 | Q10: 46 | R10: 1,5 | S10: 30 | T10: 1 | U10: 365 | V10: 12 | W10: 365 | X10: 12 | Y10: 365 | Z10: 12 | AA10: 365 | AB10: 12 | AC10: 365 | AD10: 12 | AE10: 365 | AF10: 12 | AG10: 365 | AH10: 12 | AI10: 365 | AJ10: 12 | AK10: 365 | AL10: 12 | AM10: 365 | AN10: 12 | AO10: 184 | AP10: 6 | AQ10: 365 | AR10: 12 | AS10: 365 | AT10: 12 | AU10: 1095 | AV10: 36 | AW10: 365 | AX10: 12 | AY10: 365 | AZ10: 12 | BA10: 122 | BB10: 4 | BC10: 184 | BD10: 6 | BE10: 184 | BF10: 6 | BG10: 365 | BH10: 12 | BI10: 184 | BJ10: 6
A11: 1 | B11: Заст нач. ДНДІ з ЛП | D11: 1 | E11: 1 | F11: 2 | H11: Су-24 | I11: 1 | J11: =IF(OR(J13=1,J13=2),1,0) -> 0 | K11: 1 | L11: =IF(OR(L13=1,L13=2),1,0) -> 0 | M11: 1 | N11: =IF(OR(N13=1,N13=2),1,0) -> 0 | O11: 1 | P11: =IF(OR(P13=1,P13=2),1,0) -> 0 | Q11: 1 | R11: =IF(OR(R13=1,R13=2),1,0) -> 0 | S11: 1 | T11: =IF(OR(T13=1,T13=2),1,0) -> 0
C12: п-к Чиж С.Т. | I12: =IF($D11=1,I$8,IF($D11=2,I$9,I$10)) -> 107 | J12: {=IF(MAX(IF((Main!$D$6:$D$798="ДПМУ")*(Main!$B$6:$B$798='Стан БГ'!C12)*(Main!$C$6:$C$798='Стан БГ'!H11),Main!$A$6:$A$798,0),L12,N12,P12,R12,T12)>0,MAX(IF((Main!$D$6:$D$798="ДПМУ")*(Main!$B$6:$B$798='Стан БГ'!C12)*(Main!$C$6:$C$798='Стан БГ'!H11),Main!$A$6:$A$798,0),L12,N12,P12,R12,T12),"")} | K12: =IF($D11=1,K$8,IF($D11=2,K$9,K$10)) -> 92 | L12: {=IF(MAX(IF((Main!$D$6:$D$798="ДСМУ")*(Main!$B$6:$B$798='Стан БГ'!C12)*(Main!$C$6:$C$798='Стан БГ'!H11),Main!$A$6:$A$798,0),N12,R12,T12)>0,MAX(IF((Main!$D$6:$D$798="ДСМУ")*(Main!$B$6:$B$798='Стан БГ'!C12)*(Main!$C$6:$C$798='Стан БГ'!H11),Main!$A$6:$A$798,0),N12,R12,T12),"")} | M12: =IF($D11=1,M$8,IF($D11=2,M$9,M$10)) -> 77 | N12: {=IF(MAX(IF((Main!$D$6:$D$798="ДВМП")*(Main!$B$6:$B$798='Стан БГ'!C12)*(Main!$C$6:$C$798='Стан БГ'!H11),Main!$A$6:$A$798,0),T12)>0,MAX(IF((Main!$D$6:$D$798="ДВМП")*(Main!$B$6:$B$798='Стан БГ'!C12)*(Main!$C$6:$C$798='Стан БГ'!H11),Main!$A$6:$A$798,0),T12),"")} | O12: =IF($D11=1,O$8,IF($D11=2,O$9,O$10)) -> 92 | P12: {=IF(MAX(IF((Main!$D$6:$D$798="НПМУ")*(Main!$B$6:$B$798='Стан БГ'!C12)*(Main!$C$6:$C$798='Стан БГ'!H11),Main!$A$6:$A$798,0),R12,T12)>0,MAX(IF((Main!$D$6:$D$798="НПМУ")*(Main!$B$6:$B$798='Стан БГ'!C12)*(Main!$C$6:$C$798='Стан БГ'!H11),Main!$A$6:$A$798,0),R12,T12),"")} | Q12: =IF($D11=1,Q$8,IF($D11=2,Q$9,Q$10)) -> 77 | R12: {=IF(MAX(IF((Main!$D$6:$D$798="НСМУ")*(Main!$B$6:$B$798='Стан БГ'!C12)*(Main!$C$6:$C$798='Стан БГ'!H11),Main!$A$6:$A$798,0),T12)>0,MAX(IF((Main!$D$6:$D$798="НСМУ")*(Main!$B$6:$B$798='Стан БГ'!C12)*(Main!$C$6:$C$798='Стан БГ'!H11),Main!$A$6:$A$798,0),T12),"")} | S12: =IF($D11=1,S$8,IF($D11=2,S$9,S$10)) -> 61 | T12: {=IF(MAX(IF((Main!$D$6:$D$798="НВМП")*(Main!$B$6:$B$798='Стан БГ'!C12)*(Main!$C$6:$C$798='Стан БГ'!H11),Main!$A$6:$A$798,0))>0,MAX(IF((Main!$D$6:$D$798="НВМП")*(Main!$B$6:$B$798='Стан БГ'!C12)*(Main!$C$6:$C$798='Стан БГ'!H11),Main!$A$6:$A$798,0)),"")} | U12: =IF($D11=1,U$8,IF($D11=2,U$9,IF($D11=3,U$10))) -> 365 | V12: 45777 | W12: =IF($D11=1,W$8,IF($D11=2,W$9,IF($D11=3,W$10))) -> 365 | X12: 45763 | Y12: =IF($D11=1,Y$8,IF($D11=2,Y$9,IF($D11=3,Y$10))) -> 365 | Z12: 45758 | AA12: =IF($D11=1,AA$8,IF($D11=2,AA$9,IF($D11=3,AA$10))) -> 365 | AB12: 45758 | AC12: =IF($D11=1,AC$8,IF($D11=2,AC$9,IF($D11=3,AC$10))) -> 365 | AD12: 45758 | AE12: =IF($D11=1,AE$8,IF($D11=2,AE$9,IF($D11=3,AE$10))) -> 365 | AF12: 45683 | AG12: =IF($D11=1,AG$8,IF($D11=2,AG$9,IF($D11=3,AG$10))) -> 365 | AH12: 45683 | AI12: =IF($D11=1,AI$8,IF($D11=2,AI$9,IF($D11=3,AI$10))) -> 365 | AJ12: 45776 | AK12: =IF($D11=1,AK$8,IF($D11=2,AK$9,IF($D11=3,AK$10))) -> 365 | AM12: =IF($D11=1,AM$8,IF($D11=2,AM$9,IF($D11=3,AM$10))) -> 365 | AN12: 45623 | AO12: =IF($D11=1,AO$8,IF($D11=2,AO$9,IF($D11=3,AO$10))) -> 184 | AP12: 45747 | AQ12: =IF($D11=1,AQ$8,IF($D11=2,AQ$9,IF($D11=3,AQ$10))) -> 365 | AR12: 45561 | AS12: =IF($D11=1,AS$8,IF($D11=2,AS$9,IF($D11=3,AS$10))) -> 365 | AT12: 45672 | AU12: =IF($D11=1,AU$8,IF($D11=2,AU$9,IF($D11=3,AU$10))) -> 1095 | AV12: 45756 | AW12: =IF($D11=1,AW$8,IF($D11=2,AW$9,IF($D11=3,AW$10))) -> 365 | AX12: {=IF(MAX(IF((ISNUMBER(SEARCH("Складний пілотаж",Main!$M$6:$M$798)))*(Main!$B$6:$B$798='Стан БГ'!C12),Main!$A$6:$A$798,0))>0,MAX(IF((ISNUMBER(SEARCH("Складний пілотаж",Main!$M$6:$M$798)))*(Main!$B$6:$B$798='Стан БГ'!C12),Main!$A$6:$A$798,0)),"")} | AY12: =IF($D11=1,AY$8,IF($D11=2,AY$9,IF($D11=3,AY$10))) -> 365 | AZ12: {=IF(MAX(IF((ISNUMBER(SEARCH("Мала висота",Main!$M$6:$M$798)))*(Main!$B$6:$B$798='Стан БГ'!C12),Main!$A$6:$A$798,0))>0,MAX(IF((ISNUMBER(SEARCH("Мала висота",Main!$M$6:$M$798)))*(Main!$B$6:$B$798='Стан БГ'!C12),Main!$A$6:$A$798,0)),"")} | BA12: =IF($D11=1,BA$8,IF($D11=2,BA$9,IF($D11=3,BA$10))) -> 122 | BB12: {=IF(MAX(IF((ISNUMBER(SEARCH("Гр. мала висота (ОНБ)",Main!$M$6:$M$798)))*(Main!$B$6:$B$798='Стан БГ'!C12),Main!$A$6:$A$798,0))>0,MAX(IF((ISNUMBER(SEARCH("Гр. мала висота (ОНБ)",Main!$M$6:$M$798)))*(Main!$B$6:$B$798='Стан БГ'!C12),Main!$A$6:$A$798,0)),"")} | BC12: =IF($D11=1,BC$8,IF($D11=2,BC$9,IF($D11=3,BC$10))) -> 184 | BD12: {=IF(MAX(IF((ISNUMBER(SEARCH("Бойове застосування",Main!$M$6:$M$798)))*(Main!$B$6:$B$798='Стан БГ'!C12),Main!$A$6:$A$798,0))>0,MAX(IF((ISNUMBER(SEARCH("Бойове застосування",Main!$M$6:$M$798)))*(Main!$B$6:$B$798='Стан БГ'!C12),Main!$A$6:$A$798,0)),"")} | BE12: =IF($D11=1,BE$8,IF($D11=2,BE$9,IF($D11=3,BE$10))) -> 184 | BF12: {=IF(MAX(IF((ISNUMBER(SEARCH("Групова злітаність",Main!$M$6:$M$798)))*(Main!$B$6:$B$798='Стан БГ'!C12),Main!$A$6:$A$798,0))>0,MAX(IF((ISNUMBER(SEARCH("Групова злітаність",Main!$M$6:$M$798)))*(Main!$B$6:$B$798='Стан БГ'!C12),Main!$A$6:$A$798,0)),"")} | BG12: =IF($D11=1,BG$8,IF($D11=2,BG$9,IF($D11=3,BG$10))) -> 365 | BH12: {=IF(MAX(IF((ISNUMBER(SEARCH("На десантування",Main!$M$6:$M$798)))*(Main!$B$6:$B$798='Стан БГ'!C12),Main!$A$6:$A$798,0))>0,MAX(IF((ISNUMBER(SEARCH("На десантування",Main!$M$6:$M$798)))*(Main!$B$6:$B$798='Стан БГ'!C12),Main!$A$6:$A$798,0)),"")} | BI12: =IF($D11=1,BI$8,IF($D11=2,BI$9,IF($D11=3,BI$10))) -> 184
I13: =IF(AND(J11=1,OR($G11="вп",$G11="вд",$G11="шп",$G11="оа")),1,0) -> 0 | J13: =IF(J12="",0,IF($C$2<(I12+J12)-15,2,IF($C$2<(I12+J12),1,"0"))) -> 0 | L13: =IF(L12="",0,IF($C$2<(K12+L12)-15,2,IF($C$2<(K12+L12),1,"0"))) -> 0 | N13: =IF(N12="",0,IF($C$2<(M12+N12)-15,2,IF($C$2<(M12+N12),1,"0"))) -> 0 | P13: =IF(P12="",0,IF($C$2<(O12+P12)-15,2,IF($C$2<(O12+P12),1,"0"))) -> 0 | R13: =IF(R12="",0,IF($C$2<(Q12+R12)-15,2,IF($C$2<(Q12+R12),1,"0"))) -> 0 | T13: =IF(T12="",0,IF($C$2<(S12+T12)-15,2,IF($C$2<(S12+T12),1,"0"))) -> 0 | AP13: =IF(AP12 = "",0,IF($C$2<(AO12+AP12)-15,2,IF($C$2<(AO12+AP12),1,"0"))) -> 0 | AR13: =IF(AR12 = "",0,IF($C$2<(AQ12+AR12)-15,2,IF($C$2<(AQ12+AR12),1,"0"))) -> 0
H14: Л-39 | I14: 1 | J14: =IF(OR(J16=1,J16=2),1,0) -> 0 | K14: 1 | L14: =IF(OR(L16=1,L16=2),1,0) -> 0 | M14: 1 | N14: =IF(OR(N16=1,N16=2),1,0) -> 0 | O14: 1 | P14: =IF(OR(P16=1,P16=2),1,0) -> 0 | Q14: 1 | R14: =IF(OR(R16=1,R16=2),1,0) -> 0 | S14: 1 | T14: =IF(OR(T16=1,T16=2),1,0) -> 0
I15: =I12 -> 107 | J15: {=IF(MAX(IF((Main!$D$6:$D$798="ДПМУ")*(Main!$B$6:$B$798='Стан БГ'!C12)*(Main!$C$6:$C$798='Стан БГ'!H14),Main!$A$6:$A$798,0),L15,N15,P15,R15,T15)>0,MAX(IF((Main!$D$6:$D$798="ДПМУ")*(Main!$B$6:$B$798='Стан БГ'!C12)*(Main!$C$6:$C$798='Стан БГ'!H14),Main!$A$6:$A$798,0),L15,N15,P15,R15,T15),"")} | K15: =K12 -> 92 | L15: {=IF(MAX(IF((Main!$D$6:$D$798="ДСМУ")*(Main!$B$6:$B$798='Стан БГ'!C12)*(Main!$C$6:$C$798='Стан БГ'!H14),Main!$A$6:$A$798,0),N15,R15,T15)>0,MAX(IF((Main!$D$6:$D$798="ДСМУ")*(Main!$B$6:$B$798='Стан БГ'!C12)*(Main!$C$6:$C$798='Стан БГ'!H14),Main!$A$6:$A$798,0),N15,R15,T15),"")} | M15: =M12 -> 77 | N15: {=IF(MAX(IF((Main!$D$6:$D$798="ДВМП")*(Main!$B$6:$B$798='Стан БГ'!C12)*(Main!$C$6:$C$798='Стан БГ'!H14),Main!$A$6:$A$798,0),T15)>0,MAX(IF((Main!$D$6:$D$798="ДВМП")*(Main!$B$6:$B$798='Стан БГ'!C12)*(Main!$C$6:$C$798='Стан БГ'!H14),Main!$A$6:$A$798,0),T15),"")} | O15: =O12 -> 92 | P15: {=IF(MAX(IF((Main!$D$6:$D$798="НПМУ")*(Main!$B$6:$B$798='Стан БГ'!C12)*(Main!$C$6:$C$798='Стан БГ'!H14),Main!$A$6:$A$798,0),R15,T15)>0,MAX(IF((Main!$D$6:$D$798="НПМУ")*(Main!$B$6:$B$798='Стан БГ'!C12)*(Main!$C$6:$C$798='Стан БГ'!H14),Main!$A$6:$A$798,0),R15,T15),"")} | Q15: =Q12 -> 77 | R15: {=IF(MAX(IF((Main!$D$6:$D$798="НСМУ")*(Main!$B$6:$B$798='Стан БГ'!C12)*(Main!$C$6:$C$798='Стан БГ'!H14),Main!$A$6:$A$798,0),T15)>0,MAX(IF((Main!$D$6:$D$798="НСМУ")*(Main!$B$6:$B$798='Стан БГ'!C12)*(Main!$C$6:$C$798='Стан БГ'!H14),Main!$A$6:$A$798,0),T15),"")} | S15: =S12 -> 61 | T15: {=IF(MAX(IF((Main!$D$6:$D$798="НВМП")*(Main!$B$6:$B$798='Стан БГ'!C12)*(Main!$C$6:$C$798='Стан БГ'!H14),Main!$A$6:$A$798,0))>0,MAX(IF((Main!$D$6:$D$798="НВМП")*(Main!$B$6:$B$798='Стан БГ'!C12)*(Main!$C$6:$C$798='Стан БГ'!H14),Main!$A$6:$A$798,0)),"")} | U15: =U12 -> 365 | W15: =IF($D11=1,W$8,IF($D11=2,W$9,IF($D11=3,W$10))) -> 365 | Y15: =IF($D11=1,Y$8,IF($D11=2,Y$9,IF($D11=3,Y$10))) -> 365 | AA15: =IF($D11=1,AA$8,IF($D11=2,AA$9,IF($D11=3,AA$10))) -> 365 | AC15: =IF($D11=1,AC$8,IF($D11=2,AC$9,IF($D11=3,AC$10))) -> 365 | AE15: =AE12 -> 365 | AG15: =AG12 -> 365 | AI15: =AI12 -> 365 | AK15: =AK12 -> 365 | AM15: =AM12 -> 365 | AO15: =IF($D14=1,AO$8,IF($D14=2,AO$9,IF($D14=3,AO$10))) -> FALSE | AP15: 45747 | AQ15: =IF($D14=1,AQ$8,IF($D14=2,AQ$9,IF($D14=3,AQ$10))) -> FALSE | AR15: 45733 | AS15: =IF($D14=1,AS$8,IF($D14=2,AS$9,IF($D14=3,AS$10))) -> FALSE | AU15: =IF($D14=1,AU$8,IF($D14=2,AU$9,IF($D14=3,AU$10))) -> FALSE | AW15: =IF($D11=1,AW$8,IF($D11=2,AW$9,IF($D11=3,AW$10))) -> 365 | AY15: =IF($D11=1,AY$8,IF($D11=2,AY$9,IF($D11=3,AY$10))) -> 365 | BA15: =IF($D11=1,BA$8,IF($D11=2,BA$9,IF($D11=3,BA$10))) -> 122 | BC15: =IF($D11=1,BC$8,IF($D11=2,BC$9,IF($D11=3,BC$10))) -> 184 | BE15: =BE12 -> 184 | BG15: =BG12 -> 365 | BI15: =BI12 -> 184
I16: =IF(AND(J11=1,OR($G11="вп",$G11="вд",$G11="шп",$G11="оа")),1,0) -> 0 | J16: =IF(J15="",0,IF($C$2<(I15+J15)-15,2,IF($C$2<(I15+J15),1,"0"))) -> 0 | L16: =IF(L15="",0,IF($C$2<(K15+L15)-15,2,IF($C$2<(K15+L15),1,"0"))) -> 0 | N16: =IF(N15="",0,IF($C$2<(M15+N15)-15,2,IF($C$2<(M15+N15),1,"0"))) -> 0 | P16: =IF(P15="",0,IF($C$2<(O15+P15)-15,2,IF($C$2<(O15+P15),1,"0"))) -> 0 | R16: =IF(R15="",0,IF($C$2<(Q15+R15)-15,2,IF($C$2<(Q15+R15),1,"0"))) -> 0 | T16: =IF(T15="",0,IF($C$2<(S15+T15)-15,2,IF($C$2<(S15+T15),1,"0"))) -> 0 | V16: =IF(V12 = "",0,IF($C$2<(U12+V12)-15,2,IF($C$2<(U12+V12),1,"0"))) -> 2 | X16: =IF(X12 = "",0,IF($C$2<(W12+X12)-15,2,IF($C$2<(W12+X12),1,"0"))) -> 2 | Z16: =IF(Z12 = "",0,IF($C$2<(Y12+Z12)-15,2,IF($C$2<(Y12+Z12),1,"0"))) -> 2 | AB16: =IF(AB12 = "",0,IF($C$2<(AA12+AB12)-15,2,IF($C$2<(AA12+AB12),1,"0"))) -> 2 | AD16: =IF(AD12 = "",0,IF($C$2<(AC12+AD12)-15,2,IF($C$2<(AC12+AD12),1,"0"))) -> 2 | AF16: =IF(AF12 = "",0,IF($C$2<(AE12+AF12)-15,2,IF($C$2<(AE12+AF12),1,"0"))) -> 0 | AH16: =IF(AH12 = "",0,IF($C$2<(AG12+AH12)-15,2,IF($C$2<(AG12+AH12),1,"0"))) -> 0 | AJ16: =IF(AJ12 = "",0,IF($C$2<(AI12+AJ12)-15,2,IF($C$2<(AI12+AJ12),1,"0"))) -> 2 | AL16: =IF(AL12 = "",0,IF($C$2<(AK12+AL12)-15,2,IF($C$2<(AK12+AL12),1,"0"))) -> 0 | AN16: =IF(AN12 = "",0,IF($C$2<(AM12+AN12)-15,2,IF($C$2<(AM12+AN12),1,"0"))) -> 0 | AP16: =IF(AP15 = "",0,IF($C$2<(AO12+AP15)-15,2,IF($C$2<(AO12+AP15),1,"0"))) -> 0 | AR16: =IF(AR15 = "",0,IF($C$2<(AQ12+AR15)-15,2,IF($C$2<(AQ12+AR15),1,"0"))) -> 2 | AT16: =IF(AT12 = "",0,IF($C$2<(AS12+AT12)-15,2,IF($C$2<(AS12+AT12),1,"0"))) -> 0 | AV16: =IF(AV12 = "",0,IF($C$2<(AU12+AV12)-15,2,IF($C$2<(AU12+AV12),1,"0"))) -> 2 | AX16: =IF(AX12 = "",0,IF($C$2<(AW12+AX12)-15,2,IF($C$2<(AW12+AX12),1,"0"))) -> 0 | AZ16: =IF(AZ12 = "",0,IF($C$2<(AY12+AZ12)-15,2,IF($C$2<(AY12+AZ12),1,"0"))) -> 0 | BB16: =IF(BB12 = "",0,IF($C$2<(BA12+BB12)-15,2,IF($C$2<(BA12+BB12),1,"0"))) -> 0 | BD16: =IF(BD12 = "",0,IF($C$2<(BC12+BD12)-15,2,IF($C$2<(BC12+BD12),1,"0"))) -> 0 | BF16: =IF(BF12 = "",0,IF($C$2<(BE12+BF12)-15,2,IF($C$2<(BE12+BF12),1,"0"))) -> 0 | BH16: =IF(BH12 = "",0,IF($C$2<(BG12+BH12)-15,2,IF($C$2<(BG12+BH12),1,"0"))) -> 0 | BJ16: =IF(BJ12 = "",0,IF($C$2<(BI12+BJ12)-15,2,IF($C$2<(BI12+BJ12),1,"0"))) -> 0
A17: 2 | B17: Нач. БзП ДНДІ | D17: 2 | E17: 1 | F17: 3 | H17: Мі-8 | I17: 1 | J17: =IF(OR(J19=1,J19=2),1,0) -> 0 | K17: 1 | L17: =IF(OR(L19=1,L19=2),1,0) -> 0 | M17: 1 | N17: =IF(OR(N19=1,N19=2),1,0) -> 0 | O17: 1 | P17: =IF(OR(P19=1,P19=2),1,0) -> 0 | Q17: 1 | R17: =IF(OR(R19=1,R19=2),1,0) -> 0 | S17: 1 | T17: =IF(OR(T19=1,T19=2),1,0) -> 0
C18: п/п-к Сокорський Ю.М. | I18: =IF($D17=1,I$8,IF($D17=2,I$9,I$10)) -> 92 | J18: {=IF(MAX(IF((Main!$D$6:$D$798="ДПМУ")*(Main!$B$6:$B$798='Стан БГ'!C18)*(Main!$C$6:$C$798='Стан БГ'!H17),Main!$A$6:$A$798,0),L18,N18,P18,R18,T18)>0,MAX(IF((Main!$D$6:$D$798="ДПМУ")*(Main!$B$6:$B$798='Стан БГ'!C18)*(Main!$C$6:$C$798='Стан БГ'!H17),Main!$A$6:$A$798,0),L18,N18,P18,R18,T18),"")} | K18: =IF($D17=1,K$8,IF($D17=2,K$9,K$10)) -> 77 | L18: {=IF(MAX(IF((Main!$D$6:$D$798="ДСМУ")*(Main!$B$6:$B$798='Стан БГ'!C18)*(Main!$C$6:$C$798='Стан БГ'!H17),Main!$A$6:$A$798,0),N18,R18,T18)>0,MAX(IF((Main!$D$6:$D$798="ДСМУ")*(Main!$B$6:$B$798='Стан БГ'!C18)*(Main!$C$6:$C$798='Стан БГ'!H17),Main!$A$6:$A$798,0),N18,R18,T18),"")} | M18: =IF($D17=1,M$8,IF($D17=2,M$9,M$10)) -> 61 | N18: {=IF(MAX(IF((Main!$D$6:$D$798="ДВМП")*(Main!$B$6:$B$798='Стан БГ'!C18)*(Main!$C$6:$C$798='Стан БГ'!H17),Main!$A$6:$A$798,0),T18)>0,MAX(IF((Main!$D$6:$D$798="ДВМП")*(Main!$B$6:$B$798='Стан БГ'!C18)*(Main!$C$6:$C$798='Стан БГ'!H17),Main!$A$6:$A$798,0),T18),"")} | O18: =IF($D17=1,O$8,IF($D17=2,O$9,O$10)) -> 77 | P18: {=IF(MAX(IF((Main!$D$6:$D$798="НПМУ")*(Main!$B$6:$B$798='Стан БГ'!C18)*(Main!$C$6:$C$798='Стан БГ'!H17),Main!$A$6:$A$798,0),R18,T18)>0,MAX(IF((Main!$D$6:$D$798="НПМУ")*(Main!$B$6:$B$798='Стан БГ'!C18)*(Main!$C$6:$C$798='Стан БГ'!H17),Main!$A$6:$A$798,0),R18,T18),"")} | Q18: =IF($D17=1,Q$8,IF($D17=2,Q$9,Q$10)) -> 61 | R18: {=IF(MAX(IF((Main!$D$6:$D$798="НСМУ")*(Main!$B$6:$B$798='Стан БГ'!C18)*(Main!$C$6:$C$798='Стан БГ'!H17),Main!$A$6:$A$798,0),T18)>0,MAX(IF((Main!$D$6:$D$798="НСМУ")*(Main!$B$6:$B$798='Стан БГ'!C18)*(Main!$C$6:$C$798='Стан БГ'!H17),Main!$A$6:$A$798,0),T18),"")} | S18: =IF($D17=1,S$8,IF($D17=2,S$9,S$10)) -> 46 | T18: {=IF(MAX(IF((Main!$D$6:$D$798="НВМП")*(Main!$B$6:$B$798='Стан БГ'!C18)*(Main!$C$6:$C$798='Стан БГ'!H17),Main!$A$6:$A$798,0))>0,MAX(IF((Main!$D$6:$D$798="НВМП")*(Main!$B$6:$B$798='Стан БГ'!C18)*(Main!$C$6:$C$798='Стан БГ'!H17),Main!$A$6:$A$798,0)),"")} | U18: =IF($D17=1,U$8,IF($D17=2,U$9,IF($D17=3,U$10))) -> 365 | V18: 45706 | W18: =IF($D17=1,W$8,IF($D17=2,W$9,IF($D17=3,W$10))) -> 365 | X18: 45701 | Y18: =IF($D17=1,Y$8,IF($D17=2,Y$9,IF($D17=3,Y$10))) -> 365 | Z18: 45702 | AA18: =IF($D17=1,AA$8,IF($D17=2,AA$9,IF($D17=3,AA$10))) -> 365 | AB18: 45426 | AC18: =IF($D17=1,AC$8,IF($D17=2,AC$9,IF($D17=3,AC$10))) -> 365 | AD18: 45426 | AE18: =IF($D17=1,AE$8,IF($D17=2,AE$9,IF($D17=3,AE$10))) -> 365 | AF18: 45700 | AG18: =IF($D17=1,AG$8,IF($D17=2,AG$9,IF($D17=3,AG$10))) -> 365 | AH18: 45710 | AI18: =IF($D17=1,AI$8,IF($D17=2,AI$9,IF($D17=3,AI$10))) -> 365 | AJ18: 45351 | AK18: =IF($D17=1,AK$8,IF($D17=2,AK$9,IF($D17=3,AK$10))) -> 365 | AM18: =IF($D17=1,AM$8,IF($D17=2,AM$9,IF($D17=3,AM$10))) -> 365 | AN18: 45650 | AO18: =IF($D17=1,AO$8,IF($D17=2,AO$9,IF($D17=3,AO$10))) -> 184 | AP18: 45747 | AQ18: =IF($D17=1,AQ$8,IF($D17=2,AQ$9,IF($D17=3,AQ$10))) -> 365 | AR18: 45708 | AS18: =IF($D17=1,AS$8,IF($D17=2,AS$9,IF($D17=3,AS$10))) -> 365 | AT18: 45668 | AU18: =IF($D17=1,AU$8,IF($D17=2,AU$9,IF($D17=3,AU$10))) -> 1095 | AV18: 45752 | AW18: =IF($D17=1,AW$8,IF($D17=2,AW$9,IF($D17=3,AW$10))) -> 365 | AX18: {=IF(MAX(IF((ISNUMBER(SEARCH("Складний пілотаж",Main!$M$6:$M$798)))*(Main!$B$6:$B$798='Стан БГ'!C18),Main!$A$6:$A$798,0))>0,MAX(IF((ISNUMBER(SEARCH("Складний пілотаж",Main!$M$6:$M$798)))*(Main!$B$6:$B$798='Стан БГ'!C18),Main!$A$6:$A$798,0)),"07.02.2024")} -> 07.02.2024 | AY18: =IF($D17=1,AY$8,IF($D17=2,AY$9,IF($D17=3,AY$10))) -> 365 | AZ18: {=IF(MAX(IF((ISNUMBER(SEARCH("Мала висота",Main!$M$6:$M$798)))*(Main!$B$6:$B$798='Стан БГ'!C18),Main!$A$6:$A$798,0))>0,MAX(IF((ISNUMBER(SEARCH("Мала висота",Main!$M$6:$M$798)))*(Main!$B$6:$B$798='Стан БГ'!C18),Main!$A$6:$A$798,0)),"28.04.2025")} -> 28.04.2025 | BA18: =IF($D17=1,BA$8,IF($D17=2,BA$9,IF($D17=3,BA$10))) -> 122 | BB18: {=IF(MAX(IF((ISNUMBER(SEARCH("Гр. мала висота (ОНБ)",Main!$M$6:$M$798)))*(Main!$B$6:$B$798='Стан БГ'!C18),Main!$A$6:$A$798,0))>0,MAX(IF((ISNUMBER(SEARCH("Гр. мала висота (ОНБ)",Main!$M$6:$M$798)))*(Main!$B$6:$B$798='Стан БГ'!C18),Main!$A$6:$A$798,0)),"07.02.2024")} -> 07.02.2024 | BC18: =IF($D17=1,BC$8,IF($D17=2,BC$9,IF($D17=3,BC$10))) -> 184 | BD18: {=IF(MAX(IF((ISNUMBER(SEARCH("Бойове застосування",Main!$M$6:$M$798)))*(Main!$B$6:$B$798='Стан БГ'!C18),Main!$A$6:$A$798,0))>0,MAX(IF((ISNUMBER(SEARCH("Бойове застосування",Main!$M$6:$M$798)))*(Main!$B$6:$B$798='Стан БГ'!C18),Main!$A$6:$A$798,0)),"28.04.2025")} -> 28.04.2025 | BE18: =IF($D17=1,BE$8,IF($D17=2,BE$9,IF($D17=3,BE$10))) -> 184 | BF18: {=IF(MAX(IF((ISNUMBER(SEARCH("Групова злітаність",Main!$M$6:$M$798)))*(Main!$B$6:$B$798='Стан БГ'!C18),Main!$A$6:$A$798,0))>0,MAX(IF((ISNUMBER(SEARCH("Групова злітаність",Main!$M$6:$M$798)))*(Main!$B$6:$B$798='Стан БГ'!C18),Main!$A$6:$A$798,0)),"07.02.2024")} -> 07.02.2024 | BG18: =IF($D17=1,BG$8,IF($D17=2,BG$9,IF($D17=3,BG$10))) -> 365 | BH18: {=IF(MAX(IF((ISNUMBER(SEARCH("На десантування",Main!$M$6:$M$798)))*(Main!$B$6:$B$798='Стан БГ'!C18),Main!$A$6:$A$798,0))>0,MAX(IF((ISNUMBER(SEARCH("На десантування",Main!$M$6:$M$798)))*(Main!$B$6:$B$798='Стан БГ'!C18),Main!$A$6:$A$798,0)),"")} | BI18: =IF($D17=1,BI$8,IF($D17=2,BI$9,IF($D17=3,BI$10))) -> 184
I19: =IF(AND(J17=1,OR($G17="вп",$G17="вд",$G17="шп",$G17="оа")),1,0) -> 0 | J19: =IF(J18="",0,IF($C$2<(I18+J18)-15,2,IF($C$2<(I18+J18),1,"0"))) -> 0 | L19: =IF(L18="",0,IF($C$2<(K18+L18)-15,2,IF($C$2<(K18+L18),1,"0"))) -> 0 | N19: =IF(N18="",0,IF($C$2<(M18+N18)-15,2,IF($C$2<(M18+N18),1,"0"))) -> 0 | P19: =IF(P18="",0,IF($C$2<(O18+P18)-15,2,IF($C$2<(O18+P18),1,"0"))) -> 0 | R19: =IF(R18="",0,IF($C$2<(Q18+R18)-15,2,IF($C$2<(Q18+R18),1,"0"))) -> 0 | T19: =IF(T18="",0,IF($C$2<(S18+T18)-15,2,IF($C$2<(S18+T18),1,"0"))) -> 0 | AP19: =IF(AP18 = "",0,IF($C$2<(AO18+AP18)-15,2,IF($C$2<(AO18+AP18),1,"0"))) -> 0 | AR19: =IF(AR18 = "",0,IF($C$2<(AQ18+AR18)-15,2,IF($C$2<(AQ18+AR18),1,"0"))) -> 1
H20: Мі-24 | I20: 1 | J20: 0 | L20: 0 | N20: 0 | P20: 0 | R20: 0 | T20: 0
I21: =I18 -> 92 | J21: {=IF(MAX(IF((Main!$D$6:$D$798="ДПМУ")*(Main!$B$6:$B$798='Стан БГ'!C18)*(Main!$C$6:$C$798='Стан БГ'!H20),Main!$A$6:$A$798,0),L21,N21,P21,R21,T21)>0,MAX(IF((Main!$D$6:$D$798="ДПМУ")*(Main!$B$6:$B$798='Стан БГ'!C18)*(Main!$C$6:$C$798='Стан БГ'!H120),Main!$A$6:$A$798,0),L21,N21,P21,R21,T21),"")} | K21: =K18 -> 77 | L21: {=IF(MAX(IF((Main!$D$6:$D$798="ДСМУ")*(Main!$B$6:$B$798='Стан БГ'!C18)*(Main!$C$6:$C$798='Стан БГ'!H20),Main!$A$6:$A$798,0),N21,R21,T21)>0,MAX(IF((Main!$D$6:$D$798="ДСМУ")*(Main!$B$6:$B$798='Стан БГ'!C18)*(Main!$C$6:$C$798='Стан БГ'!H120),Main!$A$6:$A$798,0),N21,R21,T21),"")} | M21: =M18 -> 61 | N21: {=IF(MAX(IF((Main!$D$6:$D$798="ДВМП")*(Main!$B$6:$B$798='Стан БГ'!C18)*(Main!$C$6:$C$798='Стан БГ'!H20),Main!$A$6:$A$798,0),T21)>0,MAX(IF((Main!$D$6:$D$798="ДВМП")*(Main!$B$6:$B$798='Стан БГ'!C18)*(Main!$C$6:$C$798='Стан БГ'!H120),Main!$A$6:$A$798,0),T21),"")} | O21: =O18 -> 77 | P21: {=IF(MAX(IF((Main!$D$6:$D$798="НПМУ")*(Main!$B$6:$B$798='Стан БГ'!C18)*(Main!$C$6:$C$798='Стан БГ'!H20),Main!$A$6:$A$798,0),R21,T21)>0,MAX(IF((Main!$D$6:$D$798="НПМУ")*(Main!$B$6:$B$798='Стан БГ'!C18)*(Main!$C$6:$C$798='Стан БГ'!H120),Main!$A$6:$A$798,0),R21,T21),"")} | Q21: =Q18 -> 61 | R21: {=IF(MAX(IF((Main!$D$6:$D$798="НСМУ")*(Main!$B$6:$B$798='Стан БГ'!C18)*(Main!$C$6:$C$798='Стан БГ'!H20),Main!$A$6:$A$798,0),T21)>0,MAX(IF((Main!$D$6:$D$798="НСМУ")*(Main!$B$6:$B$798='Стан БГ'!C18)*(Main!$C$6:$C$798='Стан БГ'!H120),Main!$A$6:$A$798,0),T21),"")} | S21: =S18 -> 46 | T21: {=IF(MAX(IF((Main!$D$6:$D$798="НВМП")*(Main!$B$6:$B$798='Стан БГ'!C18)*(Main!$C$6:$C$798='Стан БГ'!H20),Main!$A$6:$A$798,0))>0,MAX(IF((Main!$D$6:$D$798="НВМП")*(Main!$B$6:$B$798='Стан БГ'!C18)*(Main!$C$6:$C$798='Стан БГ'!H120),Main!$A$6:$A$798,0)),"")} | U21: =U18 -> 365 | W21: =IF($D17=1,W$8,IF($D17=2,W$9,IF($D17=3,W$10))) -> 365 | Y21: =IF($D17=1,Y$8,IF($D17=2,Y$9,IF($D17=3,Y$10))) -> 365 | AA21: =IF($D17=1,AA$8,IF($D17=2,AA$9,IF($D17=3,AA$10))) -> 365 | AC21: =IF($D17=1,AC$8,IF($D17=2,AC$9,IF($D17=3,AC$10))) -> 365 | AE21: =AE18 -> 365 | AG21: =AG18 -> 365 | AI21: =AI18 -> 365 | AK21: =AK18 -> 365 | AM21: =AM18 -> 365 | AO21: =IF($D20=1,AO$8,IF($D20=2,AO$9,IF($D20=3,AO$10))) -> FALSE | AQ21: =IF($D20=1,AQ$8,IF($D20=2,AQ$9,IF($D20=3,AQ$10))) -> FALSE | AR21: 45524 | AS21: =IF($D20=1,AS$8,IF($D20=2,AS$9,IF($D20=3,AS$10))) -> FALSE | AU21: =IF($D20=1,AU$8,IF($D20=2,AU$9,IF($D20=3,AU$10))) -> FALSE | AW21: =IF($D17=1,AW$8,IF($D17=2,AW$9,IF($D17=3,AW$10))) -> 365 | AY21: =IF($D17=1,AY$8,IF($D17=2,AY$9,IF($D17=3,AY$10))) -> 365 | BA21: =IF($D17=1,BA$8,IF($D17=2,BA$9,IF($D17=3,BA$10))) -> 122 | BC21: =IF($D17=1,BC$8,IF($D17=2,BC$9,IF($D17=3,BC$10))) -> 184 | BE21: =BE18 -> 184 | BG21: =BG18 -> 365 | BI21: =BI18 -> 184
I22: =IF(AND(J17=1,OR($G17="вп",$G17="вд",$G17="шп",$G17="оа")),1,0) -> 0 | J22: =IF(J21="",0,IF($C$2<(I21+J21)-15,2,IF($C$2<(I21+J21),1,"0"))) -> 0 | L22: =IF(L21="",0,IF($C$2<(K21+L21)-15,2,IF($C$2<(K21+L21),1,"0"))) -> 0 | N22: =IF(N21="",0,IF($C$2<(M21+N21)-15,2,IF($C$2<(M21+N21),1,"0"))) -> 0 | P22: =IF(P21="",0,IF($C$2<(O21+P21)-15,2,IF($C$2<(O21+P21),1,"0"))) -> 0 | R22: =IF(R21="",0,IF($C$2<(Q21+R21)-15,2,IF($C$2<(Q21+R21),1,"0"))) -> 0 | T22: =IF(T21="",0,IF($C$2<(S21+T21)-15,2,IF($C$2<(S21+T21),1,"0"))) -> 0 | V22: =IF(V18 = "",0,IF($C$2<(U18+V18)-15,2,IF($C$2<(U18+V18),1,"0"))) -> 1 | X22: =IF(X18 = "",0,IF($C$2<(W18+X18)-15,2,IF($C$2<(W18+X18),1,"0"))) -> 1 | Z22: =IF(Z18 = "",0,IF($C$2<(Y18+Z18)-15,2,IF($C$2<(Y18+Z18),1,"0"))) -> 1 | AB22: =IF(AB18 = "",0,IF($C$2<(AA18+AB18)-15,2,IF($C$2<(AA18+AB18),1,"0"))) -> 0 | AD22: =IF(AD18 = "",0,IF($C$2<(AC18+AD18)-15,2,IF($C$2<(AC18+AD18),1,"0"))) -> 0 | AF22: =IF(AF18 = "",0,IF($C$2<(AE18+AF18)-15,2,IF($C$2<(AE18+AF18),1,"0"))) -> 1 | AH22: =IF(AH18 = "",0,IF($C$2<(AG18+AH18)-15,2,IF($C$2<(AG18+AH18),1,"0"))) -> 2 | AJ22: =IF(AJ18 = "",0,IF($C$2<(AI18+AJ18)-15,2,IF($C$2<(AI18+AJ18),1,"0"))) -> 0 | AL22: =IF(AL18 = "",0,IF($C$2<(AK18+AL18)-15,2,IF($C$2<(AK18+AL18),1,"0"))) -> 0 | AN22: =IF(AN18 = "",0,IF($C$2<(AM18+AN18)-15,2,IF($C$2<(AM18+AN18),1,"0"))) -> 0 | AP22: =IF(AP21 = "",0,IF($C$2<(AO18+AP21)-15,2,IF($C$2<(AO18+AP21),1,"0"))) -> 0 | AR22: =IF(AR21 = "",0,IF($C$2<(AQ18+AR21)-15,2,IF($C$2<(AQ18+AR21),1,"0"))) -> 0 | AT22: =IF(AT18 = "",0,IF($C$2<(AS18+AT18)-15,2,IF($C$2<(AS18+AT18),1,"0"))) -> 0 | AV22: =IF(AV18 = "",0,IF($C$2<(AU18+AV18)-15,2,IF($C$2<(AU18+AV18),1,"0"))) -> 2 | AX22: =IF(AX18 = "",0,IF($C$2<(AW18+AX18)-15,2,IF($C$2<(AW18+AX18),1,"0"))) -> 0 | AZ22: =IF(AZ18 = "",0,IF($C$2<(AY18+AZ18)-15,2,IF($C$2<(AY18+AZ18),1,"0"))) -> 2 | BB22: =IF(BB18 = "",0,IF($C$2<(BA18+BB18)-15,2,IF($C$2<(BA18+BB18),1,"0"))) -> 0 | BD22: =IF(BD18 = "",0,IF($C$2<(BC18+BD18)-15,2,IF($C$2<(BC18+BD18),1,"0"))) -> 0 | BF22: =IF(BF18 = "",0,IF($C$2<(BE18+BF18)-15,2,IF($C$2<(BE18+BF18),1,"0"))) -> 0 | BH22: =IF(BH18 = "",0,IF($C$2<(BG18+BH18)-15,2,IF($C$2<(BG18+BH18),1,"0"))) -> 0 | BJ22: =IF(BJ18 = "",0,IF($C$2<(BI18+BJ18)-15,2,IF($C$2<(BI18+BJ18),1,"0"))) -> 0
A23: 3 | B23: Головний штурман | D23: 1 | E23: 1 | F23: 2 | H23: Су-24 | I23: 1 | J23: =IF(OR(J25=1,J25=2),1,0) -> 0 | K23: 1 | L23: =IF(OR(L25=1,L25=2),1,0) -> 0 | M23: 1 | N23: =IF(OR(N25=1,N25=2),1,0) -> 0 | O23: 1 | P23: =IF(OR(P25=1,P25=2),1,0) -> 0 | Q23: 1 | R23: =IF(OR(R25=1,R25=2),1,0) -> 0 | S23: 1 | T23: =IF(OR(T25=1,T25=2),1,0) -> 0
C24: п/п-к Шуляк В.М. | I24: =IF($D23=1,I$8,IF($D23=2,I$9,I$10)) -> 107 | J24: {=IF(MAX(IF((Main!$D$6:$D$798="ДПМУ")*(Main!$B$6:$B$798='Стан БГ'!C24)*(Main!$C$6:$C$798='Стан БГ'!H23),Main!$A$6:$A$798,0),L24,N24,P24,R24,T24)>0,MAX(IF((Main!$D$6:$D$798="ДПМУ")*(Main!$B$6:$B$798='Стан БГ'!C24)*(Main!$C$6:$C$798='Стан БГ'!H23),Main!$A$6:$A$798,0),L24,N24,P24,R24,T24),"")} | K24: =IF($D23=1,K$8,IF($D23=2,K$9,K$10)) -> 92 | L24: {=IF(MAX(IF((Main!$D$6:$D$798="ДСМУ")*(Main!$B$6:$B$798='Стан БГ'!C24)*(Main!$C$6:$C$798='Стан БГ'!H23),Main!$A$6:$A$798,0),N24,R24,T24)>0,MAX(IF((Main!$D$6:$D$798="ДСМУ")*(Main!$B$6:$B$798='Стан БГ'!C24)*(Main!$C$6:$C$798='Стан БГ'!H23),Main!$A$6:$A$798,0),N24,R24,T24),"")} | M24: =IF($D23=1,M$8,IF($D23=2,M$9,M$10)) -> 77 | N24: {=IF(MAX(IF((Main!$D$6:$D$798="ДВМП")*(Main!$B$6:$B$798='Стан БГ'!C24)*(Main!$C$6:$C$798='Стан БГ'!H23),Main!$A$6:$A$798,0),T24)>0,MAX(IF((Main!$D$6:$D$798="ДВМП")*(Main!$B$6:$B$798='Стан БГ'!C24)*(Main!$C$6:$C$798='Стан БГ'!H23),Main!$A$6:$A$798,0),T24),"")} | O24: =IF($D23=1,O$8,IF($D23=2,O$9,O$10)) -> 92 | P24: {=IF(MAX(IF((Main!$D$6:$D$798="НПМУ")*(Main!$B$6:$B$798='Стан БГ'!C24)*(Main!$C$6:$C$798='Стан БГ'!H23),Main!$A$6:$A$798,0),R24,T24)>0,MAX(IF((Main!$D$6:$D$798="НПМУ")*(Main!$B$6:$B$798='Стан БГ'!C24)*(Main!$C$6:$C$798='Стан БГ'!H23),Main!$A$6:$A$798,0),R24,T24),"")} | Q24: =IF($D23=1,Q$8,IF($D23=2,Q$9,Q$10)) -> 77 | R24: {=IF(MAX(IF((Main!$D$6:$D$798="НСМУ")*(Main!$B$6:$B$798='Стан БГ'!C24)*(Main!$C$6:$C$798='Стан БГ'!H23),Main!$A$6:$A$798,0),T24)>0,MAX(IF((Main!$D$6:$D$798="НСМУ")*(Main!$B$6:$B$798='Стан БГ'!C24)*(Main!$C$6:$C$798='Стан БГ'!H23),Main!$A$6:$A$798,0),T24),"")} | S24: =IF($D23=1,S$8,IF($D23=2,S$9,S$10)) -> 61 | T24: {=IF(MAX(IF((Main!$D$6:$D$798="НВМП")*(Main!$B$6:$B$798='Стан БГ'!C24)*(Main!$C$6:$C$798='Стан БГ'!H23),Main!$A$6:$A$798,0))>0,MAX(IF((Main!$D$6:$D$798="НВМП")*(Main!$B$6:$B$798='Стан БГ'!C24)*(Main!$C$6:$C$798='Стан БГ'!H23),Main!$A$6:$A$798,0)),"")} | U24: =IF($D23=1,U$8,IF($D23=2,U$9,IF($D23=3,U$10))) -> 365 | V24: 45776 | W24: =IF($D23=1,W$8,IF($D23=2,W$9,IF($D23=3,W$10))) -> 365 | X24: 45644 | Y24: =IF($D23=1,Y$8,IF($D23=2,Y$9,IF($D23=3,Y$10))) -> 365 | Z24: 45692 | AA24: =IF($D23=1,AA$8,IF($D23=2,AA$9,IF($D23=3,AA$10))) -> 365 | AB24: 45671 | AC24: =IF($D23=1,AC$8,IF($D23=2,AC$9,IF($D23=3,AC$10))) -> 365 | AD24: 45671 | AE24: =IF($D23=1,AE$8,IF($D23=2,AE$9,IF($D23=3,AE$10))) -> 365 | AF24: 45693 | AG24: =IF($D23=1,AG$8,IF($D23=2,AG$9,IF($D23=3,AG$10))) -> 365 | AH24: 45693 | AI24: =IF($D23=1,AI$8,IF($D23=2,AI$9,IF($D23=3,AI$10))) -> 365 | AJ24: 45693 | AK24: =IF($D23=1,AK$8,IF($D23=2,AK$9,IF($D23=3,AK$10))) -> 365 | AM24: =IF($D23=1,AM$8,IF($D23=2,AM$9,IF($D23=3,AM$10))) -> 365 | AN24: 45649 | AO24: =IF($D23=1,AO$8,IF($D23=2,AO$9,IF($D23=3,AO$10))) -> 184 | AP24: 45653 | AQ24: =IF($D23=1,AQ$8,IF($D23=2,AQ$9,IF($D23=3,AQ$10))) -> 365 | AR24: 45589 | AS24: =IF($D23=1,AS$8,IF($D23=2,AS$9,IF($D23=3,AS$10))) -> 365 | AT24: 45485 | AU24: =IF($D23=1,AU$8,IF($D23=2,AU$9,IF($D23=3,AU$10))) -> 1095 | AV24: 45391 | AW24: =IF($D23=1,AW$8,IF($D23=2,AW$9,IF($D23=3,AW$10))) -> 365 | AX24: {=IF(MAX(IF((ISNUMBER(SEARCH("Складний пілотаж",Main!$M$6:$M$798)))*(Main!$B$6:$B$798='Стан БГ'!C24),Main!$A$6:$A$798,0))>0,MAX(IF((ISNUMBER(SEARCH("Складний пілотаж",Main!$M$6:$M$798)))*(Main!$B$6:$B$798='Стан БГ'!C24),Main!$A$6:$A$798,0)),"18.12.2024")} -> 18.12.2024 | AY24: =IF($D23=1,AY$8,IF($D23=2,AY$9,IF($D23=3,AY$10))) -> 365 | AZ24: {=IF(MAX(IF((ISNUMBER(SEARCH("Мала висота",Main!$M$6:$M$798)))*(Main!$B$6:$B$798='Стан БГ'!C24),Main!$A$6:$A$798,0))>0,MAX(IF((ISNUMBER(SEARCH("Мала висота",Main!$M$6:$M$798)))*(Main!$B$6:$B$798='Стан БГ'!C24),Main!$A$6:$A$798,0)),"04.02.2025")} -> 04.02.2025 | BA24: =IF($D23=1,BA$8,IF($D23=2,BA$9,IF($D23=3,BA$10))) -> 122 | BB24: {=IF(MAX(IF((ISNUMBER(SEARCH("Гр. мала висота (ОНБ)",Main!$M$6:$M$798)))*(Main!$B$6:$B$798='Стан БГ'!C24),Main!$A$6:$A$798,0))>0,MAX(IF((ISNUMBER(SEARCH("Гр. мала висота (ОНБ)",Main!$M$6:$M$798)))*(Main!$B$6:$B$798='Стан БГ'!C24),Main!$A$6:$A$798,0)),"14.01.2025")} -> 14.01.2025 | BC24: =IF($D23=1,BC$8,IF($D23=2,BC$9,IF($D23=3,BC$10))) -> 184 | BD24: {=IF(MAX(IF((ISNUMBER(SEARCH("Бойове застосування",Main!$M$6:$M$798)))*(Main!$B$6:$B$798='Стан БГ'!C24),Main!$A$6:$A$798,0))>0,MAX(IF((ISNUMBER(SEARCH("Бойове застосування",Main!$M$6:$M$798)))*(Main!$B$6:$B$798='Стан БГ'!C24),Main!$A$6:$A$798,0)),"14.01.2025")} -> 14.01.2025 | BE24: =IF($D23=1,BE$8,IF($D23=2,BE$9,IF($D23=3,BE$10))) -> 184 | BF24: {=IF(MAX(IF((ISNUMBER(SEARCH("Групова злітаність",Main!$M$6:$M$798)))*(Main!$B$6:$B$798='Стан БГ'!C24),Main!$A$6:$A$798,0))>0,MAX(IF((ISNUMBER(SEARCH("Групова злітаність",Main!$M$6:$M$798)))*(Main!$B$6:$B$798='Стан БГ'!C24),Main!$A$6:$A$798,0)),"05.02.2025")} -> 05.02.2025 | BG24: =IF($D23=1,BG$8,IF($D23=2,BG$9,IF($D23=3,BG$10))) -> 365 | BH24: {=IF(MAX(IF((ISNUMBER(SEARCH("На десантування",Main!$M$6:$M$798)))*(Main!$B$6:$B$798='Стан БГ'!C24),Main!$A$6:$A$798,0))>0,MAX(IF((ISNUMBER(SEARCH("На десантування",Main!$M$6:$M$798)))*(Main!$B$6:$B$798='Стан БГ'!C24),Main!$A$6:$A$798,0)),"05.02.2025")} -> 05.02.2025 | BI24: =IF($D23=1,BI$8,IF($D23=2,BI$9,IF($D23=3,BI$10))) -> 184 | BJ24: 45693
I25: =IF(AND(J23=1,OR($G23="вп",$G23="вд",$G23="шп",$G23="оа")),1,0) -> 0 | J25: =IF(J24="",0,IF($C$2<(I24+J24)-15,2,IF($C$2<(I24+J24),1,"0"))) -> 0 | L25: =IF(L24="",0,IF($C$2<(K24+L24)-15,2,IF($C$2<(K24+L24),1,"0"))) -> 0 | N25: =IF(N24="",0,IF($C$2<(M24+N24)-15,2,IF($C$2<(M24+N24),1,"0"))) -> 0 | P25: =IF(P24="",0,IF($C$2<(O24+P24)-15,2,IF($C$2<(O24+P24),1,"0"))) -> 0 | R25: =IF(R24="",0,IF($C$2<(Q24+R24)-15,2,IF($C$2<(Q24+R24),1,"0"))) -> 0 | T25: =IF(T24="",0,IF($C$2<(S24+T24)-15,2,IF($C$2<(S24+T24),1,"0"))) -> 0 | AP25: =IF(AP24 = "",0,IF($C$2<(AO24+AP24)-15,2,IF($C$2<(AO24+AP24),1,"0"))) -> 0 | AR25: =IF(AR24 = "",0,IF($C$2<(AQ24+AR24)-15,2,IF($C$2<(AQ24+AR24),1,"0"))) -> 0
H26: Мі-8 | I26: 1 | J26: 0 | L26: 0 | N26: 0 | P26: 0 | R26: 0 | T26: 0
I27: =I24 -> 107 | J27: {=IF(MAX(IF((Main!$D$6:$D$798="ДПМУ")*(Main!$B$6:$B$798='Стан БГ'!C24)*(Main!$C$6:$C$798='Стан БГ'!H26),Main!$A$6:$A$798,0),L27,N27,P27,R27,T27)>0,MAX(IF((Main!$D$6:$D$798="ДПМУ")*(Main!$B$6:$B$798='Стан БГ'!C24)*(Main!$C$6:$C$798='Стан БГ'!H26),Main!$A$6:$A$798,0),L27,N27,P27,R27,T27),"")} | K27: =K24 -> 92 | L27: {=IF(MAX(IF((Main!$D$6:$D$798="ДСМУ")*(Main!$B$6:$B$798='Стан БГ'!C24)*(Main!$C$6:$C$798='Стан БГ'!H26),Main!$A$6:$A$798,0),N27,R27,T27)>0,MAX(IF((Main!$D$6:$D$798="ДСМУ")*(Main!$B$6:$B$798='Стан БГ'!C24)*(Main!$C$6:$C$798='Стан БГ'!H26),Main!$A$6:$A$798,0),N27,R27,T27),"")} | M27: =M24 -> 77 | N27: {=IF(MAX(IF((Main!$D$6:$D$798="ДВМП")*(Main!$B$6:$B$798='Стан БГ'!C24)*(Main!$C$6:$C$798='Стан БГ'!H26),Main!$A$6:$A$798,0),T27)>0,MAX(IF((Main!$D$6:$D$798="ДВМП")*(Main!$B$6:$B$798='Стан БГ'!C24)*(Main!$C$6:$C$798='Стан БГ'!H26),Main!$A$6:$A$798,0),T27),"")} | O27: =O24 -> 92 | P27: {=IF(MAX(IF((Main!$D$6:$D$798="НПМУ")*(Main!$B$6:$B$798='Стан БГ'!C24)*(Main!$C$6:$C$798='Стан БГ'!H26),Main!$A$6:$A$798,0),R27,T27)>0,MAX(IF((Main!$D$6:$D$798="НПМУ")*(Main!$B$6:$B$798='Стан БГ'!C24)*(Main!$C$6:$C$798='Стан БГ'!H26),Main!$A$6:$A$798,0),R27,T27),"")} | Q27: =Q24 -> 77 | R27: {=IF(MAX(IF((Main!$D$6:$D$798="НСМУ")*(Main!$B$6:$B$798='Стан БГ'!C24)*(Main!$C$6:$C$798='Стан БГ'!H26),Main!$A$6:$A$798,0),T27)>0,MAX(IF((Main!$D$6:$D$798="НСМУ")*(Main!$B$6:$B$798='Стан БГ'!C24)*(Main!$C$6:$C$798='Стан БГ'!H26),Main!$A$6:$A$798,0),T27),"")} | S27: =S24 -> 61 | T27: {=IF(MAX(IF((Main!$D$6:$D$798="НВМП")*(Main!$B$6:$B$798='Стан БГ'!C24)*(Main!$C$6:$C$798='Стан БГ'!H26),Main!$A$6:$A$798,0))>0,MAX(IF((Main!$D$6:$D$798="НВМП")*(Main!$B$6:$B$798='Стан БГ'!C24)*(Main!$C$6:$C$798='Стан БГ'!H26),Main!$A$6:$A$798,0)),"")} | U27: =U24 -> 365 | W27: =IF($D23=1,W$8,IF($D23=2,W$9,IF($D23=3,W$10))) -> 365 | Y27: =IF($D23=1,Y$8,IF($D23=2,Y$9,IF($D23=3,Y$10))) -> 365 | AA27: =IF($D23=1,AA$8,IF($D23=2,AA$9,IF($D23=3,AA$10))) -> 365 | AC27: =IF($D23=1,AC$8,IF($D23=2,AC$9,IF($D23=3,AC$10))) -> 365 | AE27: =AE24 -> 365 | AG27: =AG24 -> 365 | AI27: =AI24 -> 365 | AK27: =AK24 -> 365 | AM27: =AM24 -> 365 | AO27: =IF($D26=1,AO$8,IF($D26=2,AO$9,IF($D26=3,AO$10))) -> FALSE | AQ27: =IF($D26=1,AQ$8,IF($D26=2,AQ$9,IF($D26=3,AQ$10))) -> FALSE | AR27: 45768 | AS27: =IF($D26=1,AS$8,IF($D26=2,AS$9,IF($D26=3,AS$10))) -> FALSE | AU27: =IF($D26=1,AU$8,IF($D26=2,AU$9,IF($D26=3,AU$10))) -> FALSE | AW27: =IF($D23=1,AW$8,IF($D23=2,AW$9,IF($D23=3,AW$10))) -> 365 | AY27: =IF($D23=1,AY$8,IF($D23=2,AY$9,IF($D23=3,AY$10))) -> 365 | BA27: =IF($D23=1,BA$8,IF($D23=2,BA$9,IF($D23=3,BA$10))) -> 122 | BC27: =IF($D23=1,BC$8,IF($D23=2,BC$9,IF($D23=3,BC$10))) -> 184 | BE27: =BE24 -> 184 | BG27: =BG24 -> 365 | BI27: =BI24 -> 184
I28: =IF(AND(J23=1,OR($G23="вп",$G23="вд",$G23="шп",$G23="оа")),1,0) -> 0 | J28: =IF(J27="",0,IF($C$2<(I27+J27)-15,2,IF($C$2<(I27+J27),1,"0"))) -> 0 | L28: =IF(L27="",0,IF($C$2<(K27+L27)-15,2,IF($C$2<(K27+L27),1,"0"))) -> 0 | N28: =IF(N27="",0,IF($C$2<(M27+N27)-15,2,IF($C$2<(M27+N27),1,"0"))) -> 0 | P28: =IF(P27="",0,IF($C$2<(O27+P27)-15,2,IF($C$2<(O27+P27),1,"0"))) -> 0 | R28: =IF(R27="",0,IF($C$2<(Q27+R27)-15,2,IF($C$2<(Q27+R27),1,"0"))) -> 0 | T28: =IF(T27="",0,IF($C$2<(S27+T27)-15,2,IF($C$2<(S27+T27),1,"0"))) -> 0 | V28: =IF(V24 = "",0,IF($C$2<(U24+V24)-15,2,IF($C$2<(U24+V24),1,"0"))) -> 2 | X28: =IF(X24 = "",0,IF($C$2<(W24+X24)-15,2,IF($C$2<(W24+X24),1,"0"))) -> 0 | Z28: =IF(Z24 = "",0,IF($C$2<(Y24+Z24)-15,2,IF($C$2<(Y24+Z24),1,"0"))) -> 0 | AB28: =IF(AB24 = "",0,IF($C$2<(AA24+AB24)-15,2,IF($C$2<(AA24+AB24),1,"0"))) -> 0 | AD28: =IF(AD24 = "",0,IF($C$2<(AC24+AD24)-15,2,IF($C$2<(AC24+AD24),1,"0"))) -> 0 | AF28: =IF(AF24 = "",0,IF($C$2<(AE24+AF24)-15,2,IF($C$2<(AE24+AF24),1,"0"))) -> 0 | AH28: =IF(AH24 = "",0,IF($C$2<(AG24+AH24)-15,2,IF($C$2<(AG24+AH24),1,"0"))) -> 0 | AJ28: =IF(AJ24 = "",0,IF($C$2<(AI24+AJ24)-15,2,IF($C$2<(AI24+AJ24),1,"0"))) -> 0 | AL28: =IF(AL24 = "",0,IF($C$2<(AK24+AL24)-15,2,IF($C$2<(AK24+AL24),1,"0"))) -> 0 | AN28: =IF(AN24 = "",0,IF($C$2<(AM24+AN24)-15,2,IF($C$2<(AM24+AN24),1,"0"))) -> 0 | AP28: =IF(AP27 = "",0,IF($C$2<(AO24+AP27)-15,2,IF($C$2<(AO24+AP27),1,"0"))) -> 0 | AR28: =IF(AR27 = "",0,IF($C$2<(AQ24+AR27)-15,2,IF($C$2<(AQ24+AR27),1,"0"))) -> 2 | AT28: =IF(AT24 = "",0,IF($C$2<(AS24+AT24)-15,2,IF($C$2<(AS24+AT24),1,"0"))) -> 0 | AV28: =IF(AV24 = "",0,IF($C$2<(AU24+AV24)-15,2,IF($C$2<(AU24+AV24),1,"0"))) -> 2 | AX28: =IF(AX24 = "",0,IF($C$2<(AW24+AX24)-15,2,IF($C$2<(AW24+AX24),1,"0"))) -> 0 | AZ28: =IF(AZ24 = "",0,IF($C$2<(AY24+AZ24)-15,2,IF($C$2<(AY24+AZ24),1,"0"))) -> 0 | BB28: =IF(BB24 = "",0,IF($C$2<(BA24+BB24)-15,2,IF($C$2<(BA24+BB24),1,"0"))) -> 0 | BD28: =IF(BD24 = "",0,IF($C$2<(BC24+BD24)-15,2,IF($C$2<(BC24+BD24),1,"0"))) -> 0 | BF28: =IF(BF24 = "",0,IF($C$2<(BE24+BF24)-15,2,IF($C$2<(BE24+BF24),1,"0"))) -> 0 | BH28: =IF(BH24 = "",0,IF($C$2<(BG24+BH24)-15,2,IF($C$2<(BG24+BH24),1,"0"))) -> 0 | BJ28: =IF(BJ24 = "",0,IF($C$2<(BI24+BJ24)-15,2,IF($C$2<(BI24+BJ24),1,"0"))) -> 0
A29: 4 | B29: Начальник ЛМВ | E29: 1 | F29: =IF(E29=1,1.5,1) -> 1.5 | I29: 1 | J29: =IF(OR(J31=1,J31=2),1,0) -> 0 | K29: 1 | L29: =IF(OR(L31=1,L31=2),1,0) -> 0 | M29: 1 | N29: =IF(OR(N31=1,N31=2),1,0) -> 0 | O29: 1 | P29: =IF(OR(P31=1,P31=2),1,0) -> 0 | Q29: 1 | R29: =IF(OR(R31=1,R31=2),1,0) -> 0 | S29: 1 | T29: =IF(OR(T31=1,T31=2),1,0) -> 0
I30: =IF($D29=1,I$8,IF($D29=2,I$9,I$10)) -> 76 | J30: {=IF(MAX(IF((Main!$D$6:$D$798="ДПМУ")*(Main!$B$6:$B$798='Стан БГ'!C30)*(Main!$C$6:$C$798='Стан БГ'!H29),Main!$A$6:$A$798,0),L30,N30,P30,R30,T30)>0,MAX(IF((Main!$D$6:$D$798="ДПМУ")*(Main!$B$6:$B$798='Стан БГ'!C30)*(Main!$C$6:$C$798='Стан БГ'!H29),Main!$A$6:$A$798,0),L30,N30,P30,R30,T30),"")} | K30: =IF($D29=1,K$8,IF($D29=2,K$9,K$10)) -> 61 | L30: {=IF(MAX(IF((Main!$D$6:$D$798="ДСМУ")*(Main!$B$6:$B$798='Стан БГ'!C30)*(Main!$C$6:$C$798='Стан БГ'!H29),Main!$A$6:$A$798,0),N30,R30,T30)>0,MAX(IF((Main!$D$6:$D$798="ДСМУ")*(Main!$B$6:$B$798='Стан БГ'!C30)*(Main!$C$6:$C$798='Стан БГ'!H29),Main!$A$6:$A$798,0),N30,R30,T30),"")} | M30: =IF($D29=1,M$8,IF($D29=2,M$9,M$10)) -> 46 | N30: {=IF(MAX(IF((Main!$D$6:$D$798="ДВМП")*(Main!$B$6:$B$798='Стан БГ'!C30)*(Main!$C$6:$C$798='Стан БГ'!H29),Main!$A$6:$A$798,0),T30)>0,MAX(IF((Main!$D$6:$D$798="ДВМП")*(Main!$B$6:$B$798='Стан БГ'!C30)*(Main!$C$6:$C$798='Стан БГ'!H29),Main!$A$6:$A$798,0),T30),"")} | O30: =IF($D29=1,O$8,IF($D29=2,O$9,O$10)) -> 61 | P30: {=IF(MAX(IF((Main!$D$6:$D$798="НПМУ")*(Main!$B$6:$B$798='Стан БГ'!C30)*(Main!$C$6:$C$798='Стан БГ'!H29),Main!$A$6:$A$798,0),R30,T30)>0,MAX(IF((Main!$D$6:$D$798="НПМУ")*(Main!$B$6:$B$798='Стан БГ'!C30)*(Main!$C$6:$C$798='Стан БГ'!H29),Main!$A$6:$A$798,0),R30,T30),"")} | Q30: =IF($D29=1,Q$8,IF($D29=2,Q$9,Q$10)) -> 46 | R30: {=IF(MAX(IF((Main!$D$6:$D$798="НСМУ")*(Main!$B$6:$B$798='Стан БГ'!C30)*(Main!$C$6:$C$798='Стан БГ'!H29),Main!$A$6:$A$798,0),T30)>0,MAX(IF((Main!$D$6:$D$798="НСМУ")*(Main!$B$6:$B$798='Стан БГ'!C30)*(Main!$C$6:$C$798='Стан БГ'!H29),Main!$A$6:$A$798,0),T30),"")} | S30: =IF($D29=1,S$8,IF($D29=2,S$9,S$10)) -> 30 | T30: {=IF(MAX(IF((Main!$D$6:$D$798="НВМП")*(Main!$B$6:$B$798='Стан БГ'!C30)*(Main!$C$6:$C$798='Стан БГ'!H29),Main!$A$6:$A$798,0))>0,MAX(IF((Main!$D$6:$D$798="НВМП")*(Main!$B$6:$B$798='Стан БГ'!C30)*(Main!$C$6:$C$798='Стан БГ'!H29),Main!$A$6:$A$798,0)),"")} | U30: =IF($D29=1,U$8,IF($D29=2,U$9,IF($D29=3,U$10))) -> FALSE | W30: =IF($D29=1,W$8,IF($D29=2,W$9,IF($D29=3,W$10))) -> FALSE | Y30: =IF($D29=1,Y$8,IF($D29=2,Y$9,IF($D29=3,Y$10))) -> FALSE | AA30: =IF($D29=1,AA$8,IF($D29=2,AA$9,IF($D29=3,AA$10))) -> FALSE | AC30: =IF($D29=1,AC$8,IF($D29=2,AC$9,IF($D29=3,AC$10))) -> FALSE | AE30: =IF($D29=1,AE$8,IF($D29=2,AE$9,IF($D29=3,AE$10))) -> FALSE | AG30: =IF($D29=1,AG$8,IF($D29=2,AG$9,IF($D29=3,AG$10))) -> FALSE | AI30: =IF($D29=1,AI$8,IF($D29=2,AI$9,IF($D29=3,AI$10))) -> FALSE | AK30: =IF($D29=1,AK$8,IF($D29=2,AK$9,IF($D29=3,AK$10))) -> FALSE | AM30: =IF($D29=1,AM$8,IF($D29=2,AM$9,IF($D29=3,AM$10))) -> FALSE | AO30: =IF($D29=1,AO$8,IF($D29=2,AO$9,IF($D29=3,AO$10))) -> FALSE | AQ30: =IF($D29=1,AQ$8,IF($D29=2,AQ$9,IF($D29=3,AQ$10))) -> FALSE | AS30: =IF($D29=1,AS$8,IF($D29=2,AS$9,IF($D29=3,AS$10))) -> FALSE | AU30: =IF($D29=1,AU$8,IF($D29=2,AU$9,IF($D29=3,AU$10))) -> FALSE | AW30: =IF($D29=1,AW$8,IF($D29=2,AW$9,IF($D29=3,AW$10))) -> FALSE | AX30: {=IF(MAX(IF((ISNUMBER(SEARCH("Складний пілотаж",Main!$M$6:$M$798)))*(Main!$B$6:$B$798='Стан БГ'!C30),Main!$A$6:$A$798,0))>0,MAX(IF((ISNUMBER(SEARCH("Складний пілотаж",Main!$M$6:$M$798)))*(Main!$B$6:$B$798='Стан БГ'!C30),Main!$A$6:$A$798,0)),"")} | AY30: =IF($D29=1,AY$8,IF($D29=2,AY$9,IF($D29=3,AY$10))) -> FALSE | AZ30: {=IF(MAX(IF((ISNUMBER(SEARCH("Мала висота",Main!$M$6:$M$798)))*(Main!$B$6:$B$798='Стан БГ'!C30),Main!$A$6:$A$798,0))>0,MAX(IF((ISNUMBER(SEARCH("Мала висота",Main!$M$6:$M$798)))*(Main!$B$6:$B$798='Стан БГ'!C30),Main!$A$6:$A$798,0)),"")} | BA30: =IF($D29=1,BA$8,IF($D29=2,BA$9,IF($D29=3,BA$10))) -> FALSE | BB30: {=IF(MAX(IF((ISNUMBER(SEARCH("Гр. мала висота (ОНБ)",Main!$M$6:$M$798)))*(Main!$B$6:$B$798='Стан БГ'!C30),Main!$A$6:$A$798,0))>0,MAX(IF((ISNUMBER(SEARCH("Гр. мала висота (ОНБ)",Main!$M$6:$M$798)))*(Main!$B$6:$B$798='Стан БГ'!C30),Main!$A$6:$A$798,0)),"")} | BC30: =IF($D29=1,BC$8,IF($D29=2,BC$9,IF($D29=3,BC$10))) -> FALSE | BD30: {=IF(MAX(IF((ISNUMBER(SEARCH("Бойове застосування",Main!$M$6:$M$798)))*(Main!$B$6:$B$798='Стан БГ'!C30),Main!$A$6:$A$798,0))>0,MAX(IF((ISNUMBER(SEARCH("Бойове застосування",Main!$M$6:$M$798)))*(Main!$B$6:$B$798='Стан БГ'!C30),Main!$A$6:$A$798,0)),"")} | BE30: =IF($D29=1,BE$8,IF($D29=2,BE$9,IF($D29=3,BE$10))) -> FALSE | BF30: {=IF(MAX(IF((ISNUMBER(SEARCH("Групова злітаність",Main!$M$6:$M$798)))*(Main!$B$6:$B$798='Стан БГ'!C30),Main!$A$6:$A$798,0))>0,MAX(IF((ISNUMBER(SEARCH("Групова злітаність",Main!$M$6:$M$798)))*(Main!$B$6:$B$798='Стан БГ'!C30),Main!$A$6:$A$798,0)),"")} | BG30: =IF($D29=1,BG$8,IF($D29=2,BG$9,IF($D29=3,BG$10))) -> FALSE | BH30: {=IF(MAX(IF((ISNUMBER(SEARCH("На десантування",Main!$M$6:$M$798)))*(Main!$B$6:$B$798='Стан БГ'!C30),Main!$A$6:$A$798,0))>0,MAX(IF((ISNUMBER(SEARCH("На десантування",Main!$M$6:$M$798)))*(Main!$B$6:$B$798='Стан БГ'!C30),Main!$A$6:$A$798,0)),"")} | BI30: =IF($D29=1,BI$8,IF($D29=2,BI$9,IF($D29=3,BI$10))) -> FALSE
I31: =IF(AND(J29=1,OR($G29="вп",$G29="вд",$G29="шп",$G29="оа")),1,0) -> 0 | J31: =IF(J30="",0,IF($C$2<(I30+J30)-15,2,IF($C$2<(I30+J30),1,"0"))) -> 0 | L31: =IF(L30="",0,IF($C$2<(K30+L30)-15,2,IF($C$2<(K30+L30),1,"0"))) -> 0 | N31: =IF(N30="",0,IF($C$2<(M30+N30)-15,2,IF($C$2<(M30+N30),1,"0"))) -> 0 | P31: =IF(P30="",0,IF($C$2<(O30+P30)-15,2,IF($C$2<(O30+P30),1,"0"))) -> 0 | R31: =IF(R30="",0,IF($C$2<(Q30+R30)-15,2,IF($C$2<(Q30+R30),1,"0"))) -> 0 | T31: =IF(T30="",0,IF($C$2<(S30+T30)-15,2,IF($C$2<(S30+T30),1,"0"))) -> 0 | AP31: =IF(AP30 = "",0,IF($C$2<(AO30+AP30)-15,2,IF($C$2<(AO30+AP30),1,"0"))) -> 0 | AR31: =IF(AR30 = "",0,IF($C$2<(AQ30+AR30)-15,2,IF($C$2<(AQ30+AR30),1,"0"))) -> 0
I32: 1 | J32: 0 | L32: 0 | N32: 0 | P32: 0 | R32: 0 | T32: 0
I33: =I30 -> 76 | J33: {=IF(MAX(IF((Main!$D$6:$D$798="ДПМУ")*(Main!$B$6:$B$798='Стан БГ'!C30)*(Main!$C$6:$C$798='Стан БГ'!H32),Main!$A$6:$A$798,0),L33,N33,P33,R12,T33)>0,MAX(IF((Main!$D$6:$D$798="ДПМУ")*(Main!$B$6:$B$798='Стан БГ'!C30)*(Main!$C$6:$C$798='Стан БГ'!H32),Main!$A$6:$A$798,0),L33,N33,P33,R33,T33),"")} | K33: =K30 -> 61 | L33: {=IF(MAX(IF((Main!$D$6:$D$798="ДСМУ")*(Main!$B$6:$B$798='Стан БГ'!C30)*(Main!$C$6:$C$798='Стан БГ'!H32),Main!$A$6:$A$798,0),N33,R12,T33)>0,MAX(IF((Main!$D$6:$D$798="ДСМУ")*(Main!$B$6:$B$798='Стан БГ'!C30)*(Main!$C$6:$C$798='Стан БГ'!H32),Main!$A$6:$A$798,0),N33,R33,T33),"")} | M33: =M30 -> 46 | N33: {=IF(MAX(IF((Main!$D$6:$D$798="ДВМП")*(Main!$B$6:$B$798='Стан БГ'!C30)*(Main!$C$6:$C$798='Стан БГ'!H32),Main!$A$6:$A$798,0),T33)>0,MAX(IF((Main!$D$6:$D$798="ДВМП")*(Main!$B$6:$B$798='Стан БГ'!C30)*(Main!$C$6:$C$798='Стан БГ'!H32),Main!$A$6:$A$798,0),T33),"")} | O33: =O30 -> 61 | P33: {=IF(MAX(IF((Main!$D$6:$D$798="НПМУ")*(Main!$B$6:$B$798='Стан БГ'!C30)*(Main!$C$6:$C$798='Стан БГ'!H32),Main!$A$6:$A$798,0),R12,T33)>0,MAX(IF((Main!$D$6:$D$798="НПМУ")*(Main!$B$6:$B$798='Стан БГ'!C30)*(Main!$C$6:$C$798='Стан БГ'!H32),Main!$A$6:$A$798,0),R33,T33),"")} | Q33: =Q30 -> 46 | R33: {=IF(MAX(IF((Main!$D$6:$D$798="НСМУ")*(Main!$B$6:$B$798='Стан БГ'!C30)*(Main!$C$6:$C$798='Стан БГ'!H32),Main!$A$6:$A$798,0),T33)>0,MAX(IF((Main!$D$6:$D$798="НСМУ")*(Main!$B$6:$B$798='Стан БГ'!C30)*(Main!$C$6:$C$798='Стан БГ'!H32),Main!$A$6:$A$798,0),T33),"")} | S33: =S30 -> 30 | T33: {=IF(MAX(IF((Main!$D$6:$D$798="НВМП")*(Main!$B$6:$B$798='Стан БГ'!C30)*(Main!$C$6:$C$798='Стан БГ'!H32),Main!$A$6:$A$798,0))>0,MAX(IF((Main!$D$6:$D$798="НВМП")*(Main!$B$6:$B$798='Стан БГ'!C30)*(Main!$C$6:$C$798='Стан БГ'!H32),Main!$A$6:$A$798,0)),"")} | U33: =U30 -> FALSE | W33: =IF($D29=1,W$8,IF($D29=2,W$9,IF($D29=3,W$10))) -> FALSE | Y33: =IF($D29=1,Y$8,IF($D29=2,Y$9,IF($D29=3,Y$10))) -> FALSE | AA33: =IF($D29=1,AA$8,IF($D29=2,AA$9,IF($D29=3,AA$10))) -> FALSE | AC33: =IF($D29=1,AC$8,IF($D29=2,AC$9,IF($D29=3,AC$10))) -> FALSE | AE33: =AE30 -> FALSE | AG33: =AG30 -> FALSE | AI33: =AI30 -> FALSE | AK33: =AK30 -> FALSE | AM33: =AM30 -> FALSE | AO33: =IF($D32=1,AO$8,IF($D32=2,AO$9,IF($D32=3,AO$10))) -> FALSE | AQ33: =IF($D32=1,AQ$8,IF($D32=2,AQ$9,IF($D32=3,AQ$10))) -> FALSE | AS33: =IF($D32=1,AS$8,IF($D32=2,AS$9,IF($D32=3,AS$10))) -> FALSE | AU33: =IF($D32=1,AU$8,IF($D32=2,AU$9,IF($D32=3,AU$10))) -> FALSE | AW33: =IF($D29=1,AW$8,IF($D29=2,AW$9,IF($D29=3,AW$10))) -> FALSE | AY33: =IF($D29=1,AY$8,IF($D29=2,AY$9,IF($D29=3,AY$10))) -> FALSE | BA33: =IF($D29=1,BA$8,IF($D29=2,BA$9,IF($D29=3,BA$10))) -> FALSE | BC33: =IF($D29=1,BC$8,IF($D29=2,BC$9,IF($D29=3,BC$10))) -> FALSE | BE33: =BE30 -> FALSE | BG33: =BG30 -> FALSE | BI33: =BI30 -> FALSE
I34: =IF(AND(J29=1,OR($G29="вп",$G29="вд",$G29="шп",$G29="оа")),1,0) -> 0 | J34: =IF(J33="",0,IF($C$2<(I33+J33)-15,2,IF($C$2<(I33+J33),1,"0"))) -> 0 | L34: =IF(L33="",0,IF($C$2<(K33+L33)-15,2,IF($C$2<(K33+L33),1,"0"))) -> 0 | N34: =IF(N33="",0,IF($C$2<(M33+N33)-15,2,IF($C$2<(M33+N33),1,"0"))) -> 0 | P34: =IF(P33="",0,IF($C$2<(O33+P33)-15,2,IF($C$2<(O33+P33),1,"0"))) -> 0 | R34: =IF(R33="",0,IF($C$2<(Q33+R33)-15,2,IF($C$2<(Q33+R33),1,"0"))) -> 0 | T34: =IF(T33="",0,IF($C$2<(S33+T33)-15,2,IF($C$2<(S33+T33),1,"0"))) -> 0 | V34: =IF(V30 = "",0,IF($C$2<(U30+V30)-15,2,IF($C$2<(U30+V30),1,"0"))) -> 0 | X34: =IF(X30 = "",0,IF($C$2<(W30+X30)-15,2,IF($C$2<(W30+X30),1,"0"))) -> 0 | Z34: =IF(Z30 = "",0,IF($C$2<(Y30+Z30)-15,2,IF($C$2<(Y30+Z30),1,"0"))) -> 0 | AA34: =IF(AA30 = "",0,IF($C$2<(Z30+AA30)-15,2,IF($C$2<(Z30+AA30),1,"0"))) -> 0 | AB34: =IF(AB30 = "",0,IF($C$2<(AA30+AB30)-15,2,IF($C$2<(AA30+AB30),1,"0"))) -> 0 | AC34: =IF(AC30 = "",0,IF($C$2<(AB30+AC30)-15,2,IF($C$2<(AB30+AC30),1,"0"))) -> 0 | AD34: =IF(AD30 = "",0,IF($C$2<(AC30+AD30)-15,2,IF($C$2<(AC30+AD30),1,"0"))) -> 0 | AE34: =IF(AE30 = "",0,IF($C$2<(AD30+AE30)-15,2,IF($C$2<(AD30+AE30),1,"0"))) -> 0 | AF34: =IF(AF30 = "",0,IF($C$2<(AE30+AF30)-15,2,IF($C$2<(AE30+AF30),1,"0"))) -> 0 | AH34: =IF(AH30 = "",0,IF($C$2<(AG30+AH30)-15,2,IF($C$2<(AG30+AH30),1,"0"))) -> 0 | AJ34: =IF(AJ30 = "",0,IF($C$2<(AI30+AJ30)-15,2,IF($C$2<(AI30+AJ30),1,"0"))) -> 0 | AL34: =IF(AL30 = "",0,IF($C$2<(AK30+AL30)-15,2,IF($C$2<(AK30+AL30),1,"0"))) -> 0 | AN34: =IF(AN30 = "",0,IF($C$2<(AM30+AN30)-15,2,IF($C$2<(AM30+AN30),1,"0"))) -> 0 | AP34: =IF(AP33 = "",0,IF($C$2<(AO30+AP33)-15,2,IF($C$2<(AO30+AP33),1,"0"))) -> 0 | AR34: =IF(AR33 = "",0,IF($C$2<(AQ30+AR33)-15,2,IF($C$2<(AQ30+AR33),1,"0"))) -> 0 | AT34: =IF(AT30 = "",0,IF($C$2<(AS30+AT30)-15,2,IF($C$2<(AS30+AT30),1,"0"))) -> 0 | AV34: =IF(AV30 = "",0,IF($C$2<(AU30+AV30)-15,2,IF($C$2<(AU30+AV30),1,"0"))) -> 0 | AX34: =IF(AX30 = "",0,IF($C$2<(AW30+AX30)-15,2,IF($C$2<(AW30+AX30),1,"0"))) -> 0 | AZ34: =IF(AZ30 = "",0,IF($C$2<(AY30+AZ30)-15,2,IF($C$2<(AY30+AZ30),1,"0"))) -> 0 | BB34: =IF(BB30 = "",0,IF($C$2<(BA30+BB30)-15,2,IF($C$2<(BA30+BB30),1,"0"))) -> 0 | BD34: =IF(BD30 = "",0,IF($C$2<(BC30+BD30)-15,2,IF($C$2<(BC30+BD30),1,"0"))) -> 0 | BF34: =IF(BF30 = "",0,IF($C$2<(BE30+BF30)-15,2,IF($C$2<(BE30+BF30),1,"0"))) -> 0 | BH34: =IF(BH30 = "",0,IF($C$2<(BG30+BH30)-15,2,IF($C$2<(BG30+BH30),1,"0"))) -> 0 | BJ34: =IF(BJ30 = "",0,IF($C$2<(BI30+BJ30)-15,2,IF($C$2<(BI30+BJ30),1,"0"))) -> 0
A36: 1 | B36: Начальник ЛВК | D36: 1 | E36: 1 | F36: =IF(E36=1,1.5,1) -> 1.5 | H36: Су-24 | I36: 1 | J36: =IF(OR(J38=1,J38=2),1,0) -> 0 | K36: 1 | L36: =IF(OR(L38=1,L38=2),1,0) -> 0 | M36: 1 | N36: =IF(OR(N38=1,N38=2),1,0) -> 0 | O36: 1 | P36: =IF(OR(P38=1,P38=2),1,0) -> 0 | Q36: 1 | R36: =IF(OR(R38=1,R38=2),1,0) -> 0 | S36: 1 | T36: =IF(OR(T38=1,T38=2),1,0) -> 0
C37: п-к Чебаков М.М. | I37: =IF($D36=1,I$8,IF($D36=2,I$9,I$10)) -> 107 | J37: {=IF(MAX(IF((Main!$D$6:$D$798="ДПМУ")*(Main!$B$6:$B$798='Стан БГ'!C37)*(Main!$C$6:$C$798='Стан БГ'!H36),Main!$A$6:$A$798,0),L37,N37,P37,R37,T37)>0,MAX(IF((Main!$D$6:$D$798="ДПМУ")*(Main!$B$6:$B$798='Стан БГ'!C37)*(Main!$C$6:$C$798='Стан БГ'!H36),Main!$A$6:$A$798,0),L37,N37,P37,R37,T37),"14.05.2022")} -> 44695 | K37: =IF($D36=1,K$8,IF($D36=2,K$9,K$10)) -> 92 | L37: {=IF(MAX(IF((Main!$D$6:$D$798="ДСМУ")*(Main!$B$6:$B$798='Стан БГ'!C37)*(Main!$C$6:$C$798='Стан БГ'!H36),Main!$A$6:$A$798,0),N37,R37,T37)>0,MAX(IF((Main!$D$6:$D$798="ДСМУ")*(Main!$B$6:$B$798='Стан БГ'!C37)*(Main!$C$6:$C$798='Стан БГ'!H36),Main!$A$6:$A$798,0),N37,R37,T37),Date(2022,5,14))} -> 44695 | M37: =IF($D36=1,M$8,IF($D36=2,M$9,M$10)) -> 77 | N37: {=IF(MAX(IF((Main!$D$6:$D$798="ДВМП")*(Main!$B$6:$B$798='Стан БГ'!C37)*(Main!$C$6:$C$798='Стан БГ'!H36),Main!$A$6:$A$798,0),T37)>0,MAX(IF((Main!$D$6:$D$798="ДВМП")*(Main!$B$6:$B$798='Стан БГ'!C37)*(Main!$C$6:$C$798='Стан БГ'!H36),Main!$A$6:$A$798,0),T37),"")} | O37: =IF($D36=1,O$8,IF($D36=2,O$9,O$10)) -> 92 | P37: {=IF(MAX(IF((Main!$D$6:$D$798="НПМУ")*(Main!$B$6:$B$798='Стан БГ'!C37)*(Main!$C$6:$C$798='Стан БГ'!H36),Main!$A$6:$A$798,0),R37,T37)>0,MAX(IF((Main!$D$6:$D$798="НПМУ")*(Main!$B$6:$B$798='Стан БГ'!C37)*(Main!$C$6:$C$798='Стан БГ'!H36),Main!$A$6:$A$798,0),R37,T37),"23.04.2022")} -> 23.04.2022 | Q37: =IF($D36=1,Q$8,IF($D36=2,Q$9,Q$10)) -> 77 | R37: {=IF(MAX(IF((Main!$D$6:$D$798="НСМУ")*(Main!$B$6:$B$798='Стан БГ'!C37)*(Main!$C$6:$C$798='Стан БГ'!H36),Main!$A$6:$A$798,0),T37)>0,MAX(IF((Main!$D$6:$D$798="НСМУ")*(Main!$B$6:$B$798='Стан БГ'!C37)*(Main!$C$6:$C$798='Стан БГ'!H36),Main!$A$6:$A$798,0),T37),"23.04.2022")} -> 23.04.2022 | S37: =IF($D36=1,S$8,IF($D36=2,S$9,S$10)) -> 61 | T37: {=IF(MAX(IF((Main!$D$6:$D$798="НВМП")*(Main!$B$6:$B$798='Стан БГ'!C37)*(Main!$C$6:$C$798='Стан БГ'!H36),Main!$A$6:$A$798,0))>0,MAX(IF((Main!$D$6:$D$798="НВМП")*(Main!$B$6:$B$798='Стан БГ'!C37)*(Main!$C$6:$C$798='Стан БГ'!H36),Main!$A$6:$A$798,0)),"")} | U37: =IF($D36=1,U$8,IF($D36=2,U$9,IF($D36=3,U$10))) -> 365 | W37: =IF($D36=1,W$8,IF($D36=2,W$9,IF($D36=3,W$10))) -> 365 | X37: 45763 | Y37: =IF($D36=1,Y$8,IF($D36=2,Y$9,IF($D36=3,Y$10))) -> 365 | Z37: 45763 | AA37: =IF($D36=1,AA$8,IF($D36=2,AA$9,IF($D36=3,AA$10))) -> 365 | AC37: =IF($D36=1,AC$8,IF($D36=2,AC$9,IF($D36=3,AC$10))) -> 365 | AD37: 45763 | AE37: =IF($D36=1,AE$8,IF($D36=2,AE$9,IF($D36=3,AE$10))) -> 365 | AF37: 45763 | AG37: =IF($D36=1,AG$8,IF($D36=2,AG$9,IF($D36=3,AG$10))) -> 365 | AH37: 45763 | AI37: =IF($D36=1,AI$8,IF($D36=2,AI$9,IF($D36=3,AI$10))) -> 365 | AJ37: 45763 | AK37: =IF($D36=1,AK$8,IF($D36=2,AK$9,IF($D36=3,AK$10))) -> 365 | AM37: =IF($D36=1,AM$8,IF($D36=2,AM$9,IF($D36=3,AM$10))) -> 365 | AN37: 45653 | AO37: =IF($D36=1,AO$8,IF($D36=2,AO$9,IF($D36=3,AO$10))) -> 184 | AP37: 45761 | AQ37: =IF($D36=1,AQ$8,IF($D36=2,AQ$9,IF($D36=3,AQ$10))) -> 365 | AR37: 45553 | AS37: =IF($D36=1,AS$8,IF($D36=2,AS$9,IF($D36=3,AS$10))) -> 365 | AT37: 45682 | AU37: =IF($D36=1,AU$8,IF($D36=2,AU$9,IF($D36=3,AU$10))) -> 1095 | AV37: Зв. | AW37: =IF($D36=1,AW$8,IF($D36=2,AW$9,IF($D36=3,AW$10))) -> 365 | AX37: {=IF(MAX(IF((ISNUMBER(SEARCH("Складний пілотаж",Main!$M$6:$M$798)))*(Main!$B$6:$B$798='Стан БГ'!C37),Main!$A$6:$A$798,0))>0,MAX(IF((ISNUMBER(SEARCH("Складний пілотаж",Main!$M$6:$M$798)))*(Main!$B$6:$B$798='Стан БГ'!C37),Main!$A$6:$A$798,0)),"")} | AY37: =IF($D36=1,AY$8,IF($D36=2,AY$9,IF($D36=3,AY$10))) -> 365 | AZ37: {=IF(MAX(IF((ISNUMBER(SEARCH("Мала висота",Main!$M$6:$M$798)))*(Main!$B$6:$B$798='Стан БГ'!C37),Main!$A$6:$A$798,0))>0,MAX(IF((ISNUMBER(SEARCH("Мала висота",Main!$M$6:$M$798)))*(Main!$B$6:$B$798='Стан БГ'!C37),Main!$A$6:$A$798,0)),"")} | BA37: =IF($D36=1,BA$8,IF($D36=2,BA$9,IF($D36=3,BA$10))) -> 122 | BB37: {=IF(MAX(IF((ISNUMBER(SEARCH("Гр. мала висота (ОНБ)",Main!$M$6:$M$798)))*(Main!$B$6:$B$798='Стан БГ'!C37),Main!$A$6:$A$798,0))>0,MAX(IF((ISNUMBER(SEARCH("Гр. мала висота (ОНБ)",Main!$M$6:$M$798)))*(Main!$B$6:$B$798='Стан БГ'!C37),Main!$A$6:$A$798,0)),"")} | BC37: =IF($D36=1,BC$8,IF($D36=2,BC$9,IF($D36=3,BC$10))) -> 184 | BD37: {=IF(MAX(IF((ISNUMBER(SEARCH("Бойове застосування",Main!$M$6:$M$798)))*(Main!$B$6:$B$798='Стан БГ'!C37),Main!$A$6:$A$798,0))>0,MAX(IF((ISNUMBER(SEARCH("Бойове застосування",Main!$M$6:$M$798)))*(Main!$B$6:$B$798='Стан БГ'!C37),Main!$A$6:$A$798,0)),"")} | BE37: =IF($D36=1,BE$8,IF($D36=2,BE$9,IF($D36=3,BE$10))) -> 184 | BF37: {=IF(MAX(IF((ISNUMBER(SEARCH("Групова злітаність",Main!$M$6:$M$798)))*(Main!$B$6:$B$798='Стан БГ'!C37),Main!$A$6:$A$798,0))>0,MAX(IF((ISNUMBER(SEARCH("Групова злітаність",Main!$M$6:$M$798)))*(Main!$B$6:$B$798='Стан БГ'!C37),Main!$A$6:$A$798,0)),"")} | BG37: =IF($D36=1,BG$8,IF($D36=2,BG$9,IF($D36=3,BG$10))) -> 365 | BH37: {=IF(MAX(IF((ISNUMBER(SEARCH("На десантування",Main!$M$6:$M$798)))*(Main!$B$6:$B$798='Стан БГ'!C37),Main!$A$6:$A$798,0))>0,MAX(IF((ISNUMBER(SEARCH("На десантування",Main!$M$6:$M$798)))*(Main!$B$6:$B$798='Стан БГ'!C37),Main!$A$6:$A$798,0)),"")} | BI37: =IF($D36=1,BI$8,IF($D36=2,BI$9,IF($D36=3,BI$10))) -> 184
I38: =IF(AND(J36=1,OR($G36="вп",$G36="вд",$G36="шп",$G36="оа")),1,0) -> 0 | J38: =IF(J37="",0,IF($C$2<(I37+J37)-15,2,IF($C$2<(I37+J37),1,"0"))) -> 0 | L38: =IF(L37="",0,IF($C$2<(K37+L37)-15,2,IF($C$2<(K37+L37),1,"0"))) -> 0 | N38: =IF(N37="",0,IF($C$2<(M37+N37)-15,2,IF($C$2<(M37+N37),1,"0"))) -> 0 | P38: =IF(P37="",0,IF($C$2<(O37+P37)-15,2,IF($C$2<(O37+P37),1,"0"))) -> 0 | R38: =IF(R37="",0,IF($C$2<(Q37+R37)-15,2,IF($C$2<(Q37+R37),1,"0"))) -> 0 | T38: =IF(T37="",0,IF($C$2<(S37+T37)-15,2,IF($C$2<(S37+T37),1,"0"))) -> 0 | AP38: =IF(AP37 = "",0,IF($C$2<(AO37+AP37)-15,2,IF($C$2<(AO37+AP37),1,"0"))) -> 0 | AR38: =IF(AR37 = "",0,IF($C$2<(AQ37+AR37)-15,2,IF($C$2<(AQ37+AR37),1,"0"))) -> 0
I39: 1 | J39: 0 | L39: 0 | N39: 0 | P39: 0 | R39: 0 | T39: 0
I40: =I37 -> 107 | J40: {=IF(MAX(IF((Main!$D$6:$D$798="ДПМУ")*(Main!$B$6:$B$798='Стан БГ'!C37)*(Main!$C$6:$C$798='Стан БГ'!H39),Main!$A$6:$A$798,0),L40,N40,P40,R40,T40)>0,MAX(IF((Main!$D$6:$D$798="ДПМУ")*(Main!$B$6:$B$798='Стан БГ'!C37)*(Main!$C$6:$C$798='Стан БГ'!H39),Main!$A$6:$A$798,0),L40,N40,P40,R40,T40),"")} | K40: =K37 -> 92 | L40: {=IF(MAX(IF((Main!$D$6:$D$798="ДСМУ")*(Main!$B$6:$B$798='Стан БГ'!C37)*(Main!$C$6:$C$798='Стан БГ'!H39),Main!$A$6:$A$798,0),N40,R40,T40)>0,MAX(IF((Main!$D$6:$D$798="ДСМУ")*(Main!$B$6:$B$798='Стан БГ'!C37)*(Main!$C$6:$C$798='Стан БГ'!H39),Main!$A$6:$A$798,0),N40,R40,T40),"")} | M40: =M37 -> 77 | N40: {=IF(MAX(IF((Main!$D$6:$D$798="ДВМП")*(Main!$B$6:$B$798='Стан БГ'!C37)*(Main!$C$6:$C$798='Стан БГ'!H39),Main!$A$6:$A$798,0),T40)>0,MAX(IF((Main!$D$6:$D$798="ДВМП")*(Main!$B$6:$B$798='Стан БГ'!C37)*(Main!$C$6:$C$798='Стан БГ'!H39),Main!$A$6:$A$798,0),T40),"")} | O40: =O37 -> 92 | P40: {=IF(MAX(IF((Main!$D$6:$D$798="НПМУ")*(Main!$B$6:$B$798='Стан БГ'!C37)*(Main!$C$6:$C$798='Стан БГ'!H39),Main!$A$6:$A$798,0),R40,T40)>0,MAX(IF((Main!$D$6:$D$798="НПМУ")*(Main!$B$6:$B$798='Стан БГ'!C37)*(Main!$C$6:$C$798='Стан БГ'!H39),Main!$A$6:$A$798,0),R40,T40),"")} | Q40: =Q37 -> 77 | R40: {=IF(MAX(IF((Main!$D$6:$D$798="НСМУ")*(Main!$B$6:$B$798='Стан БГ'!C37)*(Main!$C$6:$C$798='Стан БГ'!H39),Main!$A$6:$A$798,0),T40)>0,MAX(IF((Main!$D$6:$D$798="НСМУ")*(Main!$B$6:$B$798='Стан БГ'!C37)*(Main!$C$6:$C$798='Стан БГ'!H39),Main!$A$6:$A$798,0),T40),"")} | S40: =S37 -> 61 | T40: {=IF(MAX(IF((Main!$D$6:$D$798="НВМП")*(Main!$B$6:$B$798='Стан БГ'!C37)*(Main!$C$6:$C$798='Стан БГ'!H39),Main!$A$6:$A$798,0))>0,MAX(IF((Main!$D$6:$D$798="НВМП")*(Main!$B$6:$B$798='Стан БГ'!C37)*(Main!$C$6:$C$798='Стан БГ'!H39),Main!$A$6:$A$798,0)),"")} | U40: =U37 -> 365 | W40: =IF($D36=1,W$8,IF($D36=2,W$9,IF($D36=3,W$10))) -> 365 | Y40: =IF($D36=1,Y$8,IF($D36=2,Y$9,IF($D36=3,Y$10))) -> 365 | AA40: =IF($D36=1,AA$8,IF($D36=2,AA$9,IF($D36=3,AA$10))) -> 365 | AC40: =IF($D36=1,AC$8,IF($D36=2,AC$9,IF($D36=3,AC$10))) -> 365 | AE40: =AE37 -> 365 | AG40: =AG37 -> 365 | AI40: =AI37 -> 365 | AK40: =AK37 -> 365 | AM40: =AM37 -> 365 | AO40: =IF($D39=1,AO$8,IF($D39=2,AO$9,IF($D39=3,AO$10))) -> FALSE | AQ40: =IF($D39=1,AQ$8,IF($D39=2,AQ$9,IF($D39=3,AQ$10))) -> FALSE | AR40: 45733 | AS40: =IF($D39=1,AS$8,IF($D39=2,AS$9,IF($D39=3,AS$10))) -> FALSE | AU40: =IF($D39=1,AU$8,IF($D39=2,AU$9,IF($D39=3,AU$10))) -> FALSE | AW40: =IF($D36=1,AW$8,IF($D36=2,AW$9,IF($D36=3,AW$10))) -> 365 | AY40: =IF($D36=1,AY$8,IF($D36=2,AY$9,IF($D36=3,AY$10))) -> 365 | BA40: =IF($D36=1,BA$8,IF($D36=2,BA$9,IF($D36=3,BA$10))) -> 122 | BC40: =IF($D36=1,BC$8,IF($D36=2,BC$9,IF($D36=3,BC$10))) -> 184 | BE40: =BE37 -> 184 | BG40: =BG37 -> 365 | BI40: =BI37 -> 184
I41: =IF(AND(J36=1,OR($G36="вп",$G36="вд",$G36="шп",$G36="оа")),1,0) -> 0 | J41: =IF(J40="",0,IF($C$2<(I40+J40)-15,2,IF($C$2<(I40+J40),1,"0"))) -> 0 | L41: =IF(L40="",0,IF($C$2<(K40+L40)-15,2,IF($C$2<(K40+L40),1,"0"))) -> 0 | N41: =IF(N40="",0,IF($C$2<(M40+N40)-15,2,IF($C$2<(M40+N40),1,"0"))) -> 0 | P41: =IF(P40="",0,IF($C$2<(O40+P40)-15,2,IF($C$2<(O40+P40),1,"0"))) -> 0 | R41: =IF(R40="",0,IF($C$2<(Q40+R40)-15,2,IF($C$2<(Q40+R40),1,"0"))) -> 0 | T41: =IF(T40="",0,IF($C$2<(S40+T40)-15,2,IF($C$2<(S40+T40),1,"0"))) -> 0 | V41: =IF(V37 = "",0,IF($C$2<(U37+V37)-15,2,IF($C$2<(U37+V37),1,"0"))) -> 0 | X41: =IF(X37 = "",0,IF($C$2<(W37+X37)-15,2,IF($C$2<(W37+X37),1,"0"))) -> 2 | Z41: =IF(Z37 = "",0,IF($C$2<(Y37+Z37)-15,2,IF($C$2<(Y37+Z37),1,"0"))) -> 2 | AB41: =IF(AB37 = "",0,IF($C$2<(AA37+AB37)-15,2,IF($C$2<(AA37+AB37),1,"0"))) -> 0 | AD41: =IF(AD37 = "",0,IF($C$2<(AC37+AD37)-15,2,IF($C$2<(AC37+AD37),1,"0"))) -> 2 | AF41: =IF(AF37 = "",0,IF($C$2<(AE37+AF37)-15,2,IF($C$2<(AE37+AF37),1,"0"))) -> 2 | AH41: =IF(AH37 = "",0,IF($C$2<(AG37+AH37)-15,2,IF($C$2<(AG37+AH37),1,"0"))) -> 2 | AJ41: =IF(AJ37 = "",0,IF($C$2<(AI37+AJ37)-15,2,IF($C$2<(AI37+AJ37),1,"0"))) -> 2 | AL41: =IF(AL37 = "",0,IF($C$2<(AK37+AL37)-15,2,IF($C$2<(AK37+AL37),1,"0"))) -> 0 | AN41: =IF(AN37 = "",0,IF($C$2<(AM37+AN37)-15,2,IF($C$2<(AM37+AN37),1,"0"))) -> 0 | AP41: =IF(AP40 = "",0,IF($C$2<(AO37+AP40)-15,2,IF($C$2<(AO37+AP40),1,"0"))) -> 0 | AR41: =IF(AR40 = "",0,IF($C$2<(AQ37+AR40)-15,2,IF($C$2<(AQ37+AR40),1,"0"))) -> 2 | AT41: =IF(AT37 = "",0,IF($C$2<(AS37+AT37)-15,2,IF($C$2<(AS37+AT37),1,"0"))) -> 0 | AV41: =IF(AV37 = "",0,IF($C$2<(AU37+AV37)-15,2,IF($C$2<(AU37+AV37),1,"0"))) -> #VALUE! | AX41: =IF(AX37 = "",0,IF($C$2<(AW37+AX37)-15,2,IF($C$2<(AW37+AX37),1,"0"))) -> 0 | AZ41: =IF(AZ37 = "",0,IF($C$2<(AY37+AZ37)-15,2,IF($C$2<(AY37+AZ37),1,"0"))) -> 0 | BB41: =IF(BB37 = "",0,IF($C$2<(BA37+BB37)-15,2,IF($C$2<(BA37+BB37),1,"0"))) -> 0 | BD41: =IF(BD37 = "",0,IF($C$2<(BC37+BD37)-15,2,IF($C$2<(BC37+BD37),1,"0"))) -> 0 | BF41: =IF(BF37 = "",0,IF($C$2<(BE37+BF37)-15,2,IF($C$2<(BE37+BF37),1,"0"))) -> 0 | BH41: =IF(BH37 = "",0,IF($C$2<(BG37+BH37)-15,2,IF($C$2<(BG37+BH37),1,"0"))) -> 0 | BJ41: =IF(BJ37 = "",0,IF($C$2<(BI37+BJ37)-15,2,IF($C$2<(BI37+BJ37),1,"0"))) -> 0
A42: 2 | B42: ЗН ЛВК | D42: 2 | E42: 1 | F42: =IF(E42=1,1.5,1) -> 1.5 | H42: Л-39 | I42: 1 | J42: =IF(OR(J44=1,J44=2),1,0) -> 1 | K42: 1 | L42: =IF(OR(L44=1,L44=2),1,0) -> 1 | M42: 1 | N42: =IF(OR(N44=1,N44=2),1,0) -> 0 | O42: 1 | P42: =IF(OR(P44=1,P44=2),1,0) -> 0 | Q42: 1 | R42: =IF(OR(R44=1,R44=2),1,0) -> 0 | S42: 1 | T42: =IF(OR(T44=1,T44=2),1,0) -> 0
...

Sheet Main
A1: ПОДЕННИЙ ОБЛІК НАЛЬОТУ | V1: Бойових заст.
V2: Загальний наліт | X2: Наліт на випроб | Z2: Бойових заст.
V3: К-сть | W3: Час | X3: Заг. К-сть | Y3: Заг. Час
A4: Дата | B4: ПІБ | C4: Тип ПС | D4: Час доби МУ | E4: В якості кого | F4: № КБП | G4: Вид пол. | H4: Польотів | I4: Наліт | J4: Наліт на випроб | L4: Бойових заст. | M4: Примітки | V4: =SUBTOTAL(9,H6:H499) -> 287 | W4: =SUBTOTAL(9,I6:I499) -> 8.2576389 | X4: =SUBTOTAL(9,J6:J499) -> 61 | Y4: =SUBTOTAL(9,K6:K499) -> 2.5451389 | Z4: =SUBTOTAL(9,L6:L499) -> 102
